Workbook

Sheet AAPL
A1: Date | B1: Stock Name | C1: Close
A2: 44200 | B2: AAPL | C2: 125.979
A3: 44201 | B3: AAPL | C3: 127.52
A4: 44202 | B4: AAPL | C4: 123.249
A5: 44203 | B5: AAPL | C5: 127.433
A6: 44204 | B6: AAPL | C6: 128.542
A7: 44207 | B7: AAPL | C7: 125.557
A8: 44208 | B8: AAPL | C8: 125.38
A9: 44209 | B9: AAPL | C9: 127.403
A10: 44210 | B10: AAPL | C10: 125.489
A11: 44211 | B11: AAPL | C11: 123.758
A12: 44215 | B12: AAPL | C12: 124.426
A13: 44216 | B13: AAPL | C13: 128.522
... A1256: 46022 | B1256: AAPL | C1256: 271.86

Sheet MSFT
A1: Date | B1: Stock Name | C1: Close
A2: 44200 | B2: MSFT | C2: 210.429
A3: 44201 | B3: MSFT | C3: 210.623
A4: 44202 | B4: MSFT | C4: 205.161
A5: 44203 | B5: MSFT | C5: 210.996
A6: 44204 | B6: MSFT | C6: 212.294
A7: 44207 | B7: MSFT | C7: 210.232
A8: 44208 | B8: MSFT | C8: 207.762
A9: 44209 | B9: MSFT | C9: 209.119
A10: 44210 | B10: MSFT | C10: 205.896
A11: 44211 | B11: MSFT | C11: 205.545
A12: 44215 | B12: MSFT | C12: 209.216
A13: 44216 | B13: MSFT | C13: 216.835
... A1256: 46022 | B1256: MSFT | C1256: 483.62

Sheet NVDA
A1: Date | B1: Stock Name | C1: Close
A2: 44200 | B2: NVDA | C2: 13.0804
A3: 44201 | B3: NVDA | C3: 13.3711
A4: 44202 | B4: NVDA | C4: 12.5823
A5: 44203 | B5: NVDA | C5: 13.3111
A6: 44204 | B6: NVDA | C6: 13.2432
A7: 44207 | B7: NVDA | C7: 13.5878
A8: 44208 | B8: NVDA | C8: 13.451
A9: 44209 | B9: NVDA | C9: 13.4978
A10: 44210 | B10: NVDA | C10: 13.1673
A11: 44211 | B11: NVDA | C11: 12.8268
A12: 44215 | B12: NVDA | C12: 12.9926
A13: 44216 | B13: NVDA | C13: 13.3321
... A1256: 46022 | B1256: NVDA | C1256: 186.5

Sheet AMD
A1: Date | B1: Stock Name | C1: Close
A2: 44200 | B2: AMD | C2: 92.3
A3: 44201 | B3: AMD | C3: 92.77
A4: 44202 | B4: AMD | C4: 90.33
A5: 44203 | B5: AMD | C5: 95.16
A6: 44204 | B6: AMD | C6: 94.58
A7: 44207 | B7: AMD | C7: 97.25
A8: 44208 | B8: AMD | C8: 95.355
A9: 44209 | B9: AMD | C9: 91.78
A10: 44210 | B10: AMD | C10: 90.79
A11: 44211 | B11: AMD | C11: 88.21
A12: 44215 | B12: AMD | C12: 89.45
A13: 44216 | B13: AMD | C13: 88.75
... A1256: 46022 | B1256: AMD | C1256: 214.16

Sheet AMZN
A1: Date | B1: Stock Name | C1: Close
A2: 44200 | B2: AMZN | C2: 159.332
A3: 44201 | B3: AMZN | C3: 160.926
A4: 44202 | B4: AMZN | C4: 156.919
A5: 44203 | B5: AMZN | C5: 158.108
A6: 44204 | B6: AMZN | C6: 159.135
A7: 44207 | B7: AMZN | C7: 155.71
A8: 44208 | B8: AMZN | C8: 156.041
A9: 44209 | B9: AMZN | C9: 158.294
A10: 44210 | B10: AMZN | C10: 156.373
A11: 44211 | B11: AMZN | C11: 155.212
A12: 44215 | B12: AMZN | C12: 156.038
A13: 44216 | B13: AMZN | C13: 163.169
... A1256: 46022 | B1256: AMZN | C1256: 230.82

Sheet TSLA
A1: Date | B1: Stock Name | C1: Close
A2: 44200 | B2: TSLA | C2: 243.257
A3: 44201 | B3: TSLA | C3: 245.037
A4: 44202 | B4: TSLA | C4: 251.993
A5: 44203 | B5: TSLA | C5: 272.013
A6: 44204 | B6: TSLA | C6: 293.34
A7: 44207 | B7: TSLA | C7: 270.397
A8: 44208 | B8: TSLA | C8: 283.147
A9: 44209 | B9: TSLA | C9: 284.803
A10: 44210 | B10: TSLA | C10: 281.667
A11: 44211 | B11: TSLA | C11: 275.387
A12: 44215 | B12: TSLA | C12: 281.517
A13: 44216 | B13: TSLA | C13: 283.483
... A1256: 46022 | B1256: TSLA | C1256: 449.72

Sheet GOOGL
A1: Date | B1: Stock Name | C1: Close
A2: 44200 | B2: GOOGL | C2: 85.9948
A3: 44201 | B3: GOOGL | C3: 86.6882
A4: 44202 | B4: GOOGL | C4: 85.8328
A5: 44203 | B5: GOOGL | C5: 88.3966
A6: 44204 | B6: GOOGL | C6: 89.5668
A7: 44207 | B7: GOOGL | C7: 87.4973
A8: 44208 | B8: GOOGL | C8: 86.5577
A9: 44209 | B9: GOOGL | C9: 87.0469
A10: 44210 | B10: GOOGL | C10: 86.2334
A11: 44211 | B11: GOOGL | C11: 86.0691
A12: 44215 | B12: GOOGL | C12: 88.9012
A13: 44216 | B13: GOOGL | C13: 93.664
... A1256: 46022 | B1256: GOOGL | C1256: 313

Sheet META
A1: Date | B1: Stock Name | C1: Close
A2: 44200 | B2: META | C2: 268.94
A3: 44201 | B3: META | C3: 270.97
A4: 44202 | B4: META | C4: 263.31
A5: 44203 | B5: META | C5: 268.74
A6: 44204 | B6: META | C6: 267.57
A7: 44207 | B7: META | C7: 256.84
A8: 44208 | B8: META | C8: 251.09
A9: 44209 | B9: META | C9: 251.64
A10: 44210 | B10: META | C10: 245.64
A11: 44211 | B11: META | C11: 251.36
A12: 44215 | B12: META | C12: 261.1
A13: 44216 | B13: META | C13: 267.48
... A1281: 46059 | B1281: META | C1281: 661.46

Sheet Nasdaq
A1: Date | B1: Index Name | C1: Close
A2: 44200 | B2: Nasdaq | C2: 12698.45
A3: 44201 | B3: Nasdaq | C3: 12818.96
A4: 44202 | B4: Nasdaq | C4: 12740.79
A5: 44203 | B5: Nasdaq | C5: 13067.48
A6: 44204 | B6: Nasdaq | C6: 13201.98
A7: 44207 | B7: Nasdaq | C7: 13036.43
A8: 44208 | B8: Nasdaq | C8: 13072.43
A9: 44209 | B9: Nasdaq | C9: 13128.95
A10: 44210 | B10: Nasdaq | C10: 13112.64
A11: 44211 | B11: Nasdaq | C11: 12998.5
A12: 44215 | B12: Nasdaq | C12: 13197.18
A13: 44216 | B13: Nasdaq | C13: 13457.25
... A1256: 46022 | B1256: Nasdaq | C1256: 23241.99

Sheet Risk_free_rate
A1: 10Y Govt. Bomd | B1: 0.0422

Sheet Raw_Stock_Data
A1: Date | B1: AAPL | C1: MSFT | D1: NVDA | E1: AMD | F1: AMZN | G1: TSLA | H1: GOOGL | I1: META | J1: Nasdaq
A2: 44200 | B2: =VLOOKUP(A2,AAPL!A1:C1256,3) -> 125.979 | C2: =VLOOKUP(A2,MSFT!A1:C1256,3) -> 210.429 | D2: =VLOOKUP(A2,NVDA!A1:C1256,3) -> 13.0804 | E2: =VLOOKUP(A2,AMD!A1:C1256,3) -> 92.3 | F2: =VLOOKUP(A2,AMZN!A1:C1256,3) -> 159.332 | G2: =VLOOKUP(A2,TSLA!A1:C1256,3) -> 243.257 | H2: =VLOOKUP(A2,GOOGL!A1:C1256,3) -> 85.9948 | I2: =VLOOKUP(A2,META!A1:C1256,3) -> 268.94 | J2: =VLOOKUP(A2,Nasdaq!A1:C1256,3) -> 12698.45
A3: 44201 | B3: =VLOOKUP(A3,AAPL!A2:C1257,3) -> 127.52 | C3: =VLOOKUP(A3,MSFT!A2:C1257,3) -> 210.623 | D3: =VLOOKUP(A3,NVDA!A2:C1257,3) -> 13.3711 | E3: =VLOOKUP(A3,AMD!A2:C1257,3) -> 92.77 | F3: =VLOOKUP(A3,AMZN!A2:C1257,3) -> 160.926 | G3: =VLOOKUP(A3,TSLA!A2:C1257,3) -> 245.037 | H3: =VLOOKUP(A3,GOOGL!A2:C1257,3) -> 86.6882 | I3: =VLOOKUP(A3,META!A2:C1257,3) -> 270.97 | J3: =VLOOKUP(A3,Nasdaq!A2:C1257,3) -> 12818.96
A4: 44202 | B4: =VLOOKUP(A4,AAPL!A3:C1258,3) -> 123.249 | C4: =VLOOKUP(A4,MSFT!A3:C1258,3) -> 205.161 | D4: =VLOOKUP(A4,NVDA!A3:C1258,3) -> 12.5823 | E4: =VLOOKUP(A4,AMD!A3:C1258,3) -> 90.33 | F4: =VLOOKUP(A4,AMZN!A3:C1258,3) -> 156.919 | G4: =VLOOKUP(A4,TSLA!A3:C1258,3) -> 251.993 | H4: =VLOOKUP(A4,GOOGL!A3:C1258,3) -> 85.8328 | I4: =VLOOKUP(A4,META!A3:C1258,3) -> 263.31 | J4: =VLOOKUP(A4,Nasdaq!A3:C1258,3) -> 12740.79
A5: 44203 | B5: =VLOOKUP(A5,AAPL!A4:C1259,3) -> 127.433 | C5: =VLOOKUP(A5,MSFT!A4:C1259,3) -> 210.996 | D5: =VLOOKUP(A5,NVDA!A4:C1259,3) -> 13.3111 | E5: =VLOOKUP(A5,AMD!A4:C1259,3) -> 95.16 | F5: =VLOOKUP(A5,AMZN!A4:C1259,3) -> 158.108 | G5: =VLOOKUP(A5,TSLA!A4:C1259,3) -> 272.013 | H5: =VLOOKUP(A5,GOOGL!A4:C1259,3) -> 88.3966 | I5: =VLOOKUP(A5,META!A4:C1259,3) -> 268.74 | J5: =VLOOKUP(A5,Nasdaq!A4:C1259,3) -> 13067.48
A6: 44204 | B6: =VLOOKUP(A6,AAPL!A5:C1260,3) -> 128.542 | C6: =VLOOKUP(A6,MSFT!A5:C1260,3) -> 212.294 | D6: =VLOOKUP(A6,NVDA!A5:C1260,3) -> 13.2432 | E6: =VLOOKUP(A6,AMD!A5:C1260,3) -> 94.58 | F6: =VLOOKUP(A6,AMZN!A5:C1260,3) -> 159.135 | G6: =VLOOKUP(A6,TSLA!A5:C1260,3) -> 293.34 | H6: =VLOOKUP(A6,GOOGL!A5:C1260,3) -> 89.5668 | I6: =VLOOKUP(A6,META!A5:C1260,3) -> 267.57 | J6: =VLOOKUP(A6,Nasdaq!A5:C1260,3) -> 13201.98
A7: 44207 | B7: =VLOOKUP(A7,AAPL!A6:C1261,3) -> 125.557 | C7: =VLOOKUP(A7,MSFT!A6:C1261,3) -> 210.232 | D7: =VLOOKUP(A7,NVDA!A6:C1261,3) -> 13.5878 | E7: =VLOOKUP(A7,AMD!A6:C1261,3) -> 97.25 | F7: =VLOOKUP(A7,AMZN!A6:C1261,3) -> 155.71 | G7: =VLOOKUP(A7,TSLA!A6:C1261,3) -> 270.397 | H7: =VLOOKUP(A7,GOOGL!A6:C1261,3) -> 87.4973 | I7: =VLOOKUP(A7,META!A6:C1261,3) -> 256.84 | J7: =VLOOKUP(A7,Nasdaq!A6:C1261,3) -> 13036.43
A8: 44208 | B8: =VLOOKUP(A8,AAPL!A7:C1262,3) -> 125.38 | C8: =VLOOKUP(A8,MSFT!A7:C1262,3) -> 207.762 | D8: =VLOOKUP(A8,NVDA!A7:C1262,3) -> 13.451 | E8: =VLOOKUP(A8,AMD!A7:C1262,3) -> 95.355 | F8: =VLOOKUP(A8,AMZN!A7:C1262,3) -> 156.041 | G8: =VLOOKUP(A8,TSLA!A7:C1262,3) -> 283.147 | H8: =VLOOKUP(A8,GOOGL!A7:C1262,3) -> 86.5577 | I8: =VLOOKUP(A8,META!A7:C1262,3) -> 251.09 | J8: =VLOOKUP(A8,Nasdaq!A7:C1262,3) -> 13072.43
A9: 44209 | B9: =VLOOKUP(A9,AAPL!A8:C1263,3) -> 127.403 | C9: =VLOOKUP(A9,MSFT!A8:C1263,3) -> 209.119 | D9: =VLOOKUP(A9,NVDA!A8:C1263,3) -> 13.4978 | E9: =VLOOKUP(A9,AMD!A8:C1263,3) -> 91.78 | F9: =VLOOKUP(A9,AMZN!A8:C1263,3) -> 158.294 | G9: =VLOOKUP(A9,TSLA!A8:C1263,3) -> 284.803 | H9: =VLOOKUP(A9,GOOGL!A8:C1263,3) -> 87.0469 | I9: =VLOOKUP(A9,META!A8:C1263,3) -> 251.64 | J9: =VLOOKUP(A9,Nasdaq!A8:C1263,3) -> 13128.95
A10: 44210 | B10: =VLOOKUP(A10,AAPL!A9:C1264,3) -> 125.489 | C10: =VLOOKUP(A10,MSFT!A9:C1264,3) -> 205.896 | D10: =VLOOKUP(A10,NVDA!A9:C1264,3) -> 13.1673 | E10: =VLOOKUP(A10,AMD!A9:C1264,3) -> 90.79 | F10: =VLOOKUP(A10,AMZN!A9:C1264,3) -> 156.373 | G10: =VLOOKUP(A10,TSLA!A9:C1264,3) -> 281.667 | H10: =VLOOKUP(A10,GOOGL!A9:C1264,3) -> 86.2334 | I10: =VLOOKUP(A10,META!A9:C1264,3) -> 245.64 | J10: =VLOOKUP(A10,Nasdaq!A9:C1264,3) -> 13112.64
A11: 44211 | B11: =VLOOKUP(A11,AAPL!A10:C1265,3) -> 123.758 | C11: =VLOOKUP(A11,MSFT!A10:C1265,3) -> 205.545 | D11: =VLOOKUP(A11,NVDA!A10:C1265,3) -> 12.8268 | E11: =VLOOKUP(A11,AMD!A10:C1265,3) -> 88.21 | F11: =VLOOKUP(A11,AMZN!A10:C1265,3) -> 155.212 | G11: =VLOOKUP(A11,TSLA!A10:C1265,3) -> 275.387 | H11: =VLOOKUP(A11,GOOGL!A10:C1265,3) -> 86.0691 | I11: =VLOOKUP(A11,META!A10:C1265,3) -> 251.36 | J11: =VLOOKUP(A11,Nasdaq!A10:C1265,3) -> 12998.5
A12: 44215 | B12: =VLOOKUP(A12,AAPL!A11:C1266,3) -> 124.426 | C12: =VLOOKUP(A12,MSFT!A11:C1266,3) -> 209.216 | D12: =VLOOKUP(A12,NVDA!A11:C1266,3) -> 12.9926 | E12: =VLOOKUP(A12,AMD!A11:C1266,3) -> 89.45 | F12: =VLOOKUP(A12,AMZN!A11:C1266,3) -> 156.038 | G12: =VLOOKUP(A12,TSLA!A11:C1266,3) -> 281.517 | H12: =VLOOKUP(A12,GOOGL!A11:C1266,3) -> 88.9012 | I12: =VLOOKUP(A12,META!A11:C1266,3) -> 261.1 | J12: =VLOOKUP(A12,Nasdaq!A11:C1266,3) -> 13197.18
A13: 44216 | B13: =VLOOKUP(A13,AAPL!A12:C1267,3) -> 128.522 | C13: =VLOOKUP(A13,MSFT!A12:C1267,3) -> 216.835 | D13: =VLOOKUP(A13,NVDA!A12:C1267,3) -> 13.3321 | E13: =VLOOKUP(A13,AMD!A12:C1267,3) -> 88.75 | F13: =VLOOKUP(A13,AMZN!A12:C1267,3) -> 163.169 | G13: =VLOOKUP(A13,TSLA!A12:C1267,3) -> 283.483 | H13: =VLOOKUP(A13,GOOGL!A12:C1267,3) -> 93.664 | I13: =VLOOKUP(A13,META!A12:C1267,3) -> 267.48 | J13: =VLOOKUP(A13,Nasdaq!A12:C1267,3) -> 13457.25
... A1256: 46022 | B1256: =VLOOKUP(A1256,AAPL!A1255:C2510,3) -> 271.86 | C1256: =VLOOKUP(A1256,MSFT!A1255:C2510,3) -> 483.62 | D1256: =VLOOKUP(A1256,NVDA!A1255:C2510,3) -> 186.5 | E1256: =VLOOKUP(A1256,AMD!A1255:C2510,3) -> 214.16 | F1256: =VLOOKUP(A1256,AMZN!A1255:C2510,3) -> 230.82 | G1256: =VLOOKUP(A1256,TSLA!A1255:C2510,3) -> 449.72 | H1256: =VLOOKUP(A1256,GOOGL!A1255:C2510,3) -> 313 | I1256: =VLOOKUP(A1256,META!A1255:C2510,3) -> 660.09 | J1256: =VLOOKUP(A1256,Nasdaq!A1255:C2510,3) -> 23241.99

Sheet Daily_returns_cal
A1: Date | B1: AAPL | C1: MSFT | D1: NVDA | E1: AMD | F1: AMZN | G1: TSLA | H1: GOOGL | I1: META | J1: Nasdaq
A2: 44200
A3: 44201 | B3: =(Raw_Stock_Data!B3/Raw_Stock_Data!B2)-1 -> 0.012232197 | C3: =(Raw_Stock_Data!C3/Raw_Stock_Data!C2)-1 -> 0.00092192616 | D3: =(Raw_Stock_Data!D3/Raw_Stock_Data!D2)-1 -> 0.022224091 | E3: =(Raw_Stock_Data!E3/Raw_Stock_Data!E2)-1 -> 0.005092091 | F3: =(Raw_Stock_Data!F3/Raw_Stock_Data!F2)-1 -> 0.010004268 | G3: =(Raw_Stock_Data!G3/Raw_Stock_Data!G2)-1 -> 0.0073173639 | H3: =(Raw_Stock_Data!H3/Raw_Stock_Data!H2)-1 -> 0.0080632782 | I3: =(Raw_Stock_Data!I3/Raw_Stock_Data!I2)-1 -> 0.007548152 | J3: =(Raw_Stock_Data!J3/Raw_Stock_Data!J2)-1 -> 0.0094901346
A4: 44202 | B4: =(Raw_Stock_Data!B4/Raw_Stock_Data!B3)-1 -> -0.033492785 | C4: =(Raw_Stock_Data!C4/Raw_Stock_Data!C3)-1 -> -0.02593259 | D4: =(Raw_Stock_Data!D4/Raw_Stock_Data!D3)-1 -> -0.058992903 | E4: =(Raw_Stock_Data!E4/Raw_Stock_Data!E3)-1 -> -0.026301606 | F4: =(Raw_Stock_Data!F4/Raw_Stock_Data!F3)-1 -> -0.024899643 | G4: =(Raw_Stock_Data!G4/Raw_Stock_Data!G3)-1 -> 0.02838755 | H4: =(Raw_Stock_Data!H4/Raw_Stock_Data!H3)-1 -> -0.0098675483 | I4: =(Raw_Stock_Data!I4/Raw_Stock_Data!I3)-1 -> -0.028268812 | J4: =(Raw_Stock_Data!J4/Raw_Stock_Data!J3)-1 -> -0.0060979986
A5: 44203 | B5: =(Raw_Stock_Data!B5/Raw_Stock_Data!B4)-1 -> 0.033947537 | C5: =(Raw_Stock_Data!C5/Raw_Stock_Data!C4)-1 -> 0.028441078 | D5: =(Raw_Stock_Data!D5/Raw_Stock_Data!D4)-1 -> 0.057922637 | E5: =(Raw_Stock_Data!E5/Raw_Stock_Data!E4)-1 -> 0.053470608 | F5: =(Raw_Stock_Data!F5/Raw_Stock_Data!F4)-1 -> 0.0075771576 | G5: =(Raw_Stock_Data!G5/Raw_Stock_Data!G4)-1 -> 0.079446651 | H5: =(Raw_Stock_Data!H5/Raw_Stock_Data!H4)-1 -> 0.0298697 | I5: =(Raw_Stock_Data!I5/Raw_Stock_Data!I4)-1 -> 0.02062208 | J5: =(Raw_Stock_Data!J5/Raw_Stock_Data!J4)-1 -> 0.025641267
A6: 44204 | B6: =(Raw_Stock_Data!B6/Raw_Stock_Data!B5)-1 -> 0.0087026124 | C6: =(Raw_Stock_Data!C6/Raw_Stock_Data!C5)-1 -> 0.0061517754 | D6: =(Raw_Stock_Data!D6/Raw_Stock_Data!D5)-1 -> -0.0051010059 | E6: =(Raw_Stock_Data!E6/Raw_Stock_Data!E5)-1 -> -0.0060949979 | F6: =(Raw_Stock_Data!F6/Raw_Stock_Data!F5)-1 -> 0.00649556 | G6: =(Raw_Stock_Data!G6/Raw_Stock_Data!G5)-1 -> 0.078404341 | H6: =(Raw_Stock_Data!H6/Raw_Stock_Data!H5)-1 -> 0.013238066 | I6: =(Raw_Stock_Data!I6/Raw_Stock_Data!I5)-1 -> -0.0043536504 | J6: =(Raw_Stock_Data!J6/Raw_Stock_Data!J5)-1 -> 0.010292727
A7: 44207 | B7: =(Raw_Stock_Data!B7/Raw_Stock_Data!B6)-1 -> -0.023221982 | C7: =(Raw_Stock_Data!C7/Raw_Stock_Data!C6)-1 -> -0.0097129453 | D7: =(Raw_Stock_Data!D7/Raw_Stock_Data!D6)-1 -> 0.026020901 | E7: =(Raw_Stock_Data!E7/Raw_Stock_Data!E6)-1 -> 0.02823007 | F7: =(Raw_Stock_Data!F7/Raw_Stock_Data!F6)-1 -> -0.021522607 | G7: =(Raw_Stock_Data!G7/Raw_Stock_Data!G6)-1 -> -0.078212995 | H7: =(Raw_Stock_Data!H7/Raw_Stock_Data!H6)-1 -> -0.02310566 | I7: =(Raw_Stock_Data!I7/Raw_Stock_Data!I6)-1 -> -0.040101656 | J7: =(Raw_Stock_Data!J7/Raw_Stock_Data!J6)-1 -> -0.012539786
A8: 44208 | B8: =(Raw_Stock_Data!B8/Raw_Stock_Data!B7)-1 -> -0.0014097183 | C8: =(Raw_Stock_Data!C8/Raw_Stock_Data!C7)-1 -> -0.011748925 | D8: =(Raw_Stock_Data!D8/Raw_Stock_Data!D7)-1 -> -0.010067855 | E8: =(Raw_Stock_Data!E8/Raw_Stock_Data!E7)-1 -> -0.019485861 | F8: =(Raw_Stock_Data!F8/Raw_Stock_Data!F7)-1 -> 0.0021257466 | G8: =(Raw_Stock_Data!G8/Raw_Stock_Data!G7)-1 -> 0.04715289 | H8: =(Raw_Stock_Data!H8/Raw_Stock_Data!H7)-1 -> -0.010738617 | I8: =(Raw_Stock_Data!I8/Raw_Stock_Data!I7)-1 -> -0.022387479 | J8: =(Raw_Stock_Data!J8/Raw_Stock_Data!J7)-1 -> 0.0027614922
A9: 44209 | B9: =(Raw_Stock_Data!B9/Raw_Stock_Data!B8)-1 -> 0.01613495 | C9: =(Raw_Stock_Data!C9/Raw_Stock_Data!C8)-1 -> 0.006531512 | D9: =(Raw_Stock_Data!D9/Raw_Stock_Data!D8)-1 -> 0.0034792952 | E9: =(Raw_Stock_Data!E9/Raw_Stock_Data!E8)-1 -> -0.037491479 | F9: =(Raw_Stock_Data!F9/Raw_Stock_Data!F8)-1 -> 0.014438513 | G9: =(Raw_Stock_Data!G9/Raw_Stock_Data!G8)-1 -> 0.0058485522 | H9: =(Raw_Stock_Data!H9/Raw_Stock_Data!H8)-1 -> 0.0056517213 | I9: =(Raw_Stock_Data!I9/Raw_Stock_Data!I8)-1 -> 0.0021904496 | J9: =(Raw_Stock_Data!J9/Raw_Stock_Data!J8)-1 -> 0.0043236032
A10: 44210 | B10: =(Raw_Stock_Data!B10/Raw_Stock_Data!B9)-1 -> -0.015023194 | C10: =(Raw_Stock_Data!C10/Raw_Stock_Data!C9)-1 -> -0.015412277 | D10: =(Raw_Stock_Data!D10/Raw_Stock_Data!D9)-1 -> -0.024485472 | E10: =(Raw_Stock_Data!E10/Raw_Stock_Data!E9)-1 -> -0.010786664 | F10: =(Raw_Stock_Data!F10/Raw_Stock_Data!F9)-1 -> -0.012135646 | G10: =(Raw_Stock_Data!G10/Raw_Stock_Data!G9)-1 -> -0.01101112 | H10: =(Raw_Stock_Data!H10/Raw_Stock_Data!H9)-1 -> -0.0093455367 | I10: =(Raw_Stock_Data!I10/Raw_Stock_Data!I9)-1 -> -0.023843586 | J10: =(Raw_Stock_Data!J10/Raw_Stock_Data!J9)-1 -> -0.0012422928
A11: 44211 | B11: =(Raw_Stock_Data!B11/Raw_Stock_Data!B10)-1 -> -0.013794038 | C11: =(Raw_Stock_Data!C11/Raw_Stock_Data!C10)-1 -> -0.0017047441 | D11: =(Raw_Stock_Data!D11/Raw_Stock_Data!D10)-1 -> -0.025859516 | E11: =(Raw_Stock_Data!E11/Raw_Stock_Data!E10)-1 -> -0.028417227 | F11: =(Raw_Stock_Data!F11/Raw_Stock_Data!F10)-1 -> -0.0074245554 | G11: =(Raw_Stock_Data!G11/Raw_Stock_Data!G10)-1 -> -0.022295832 | H11: =(Raw_Stock_Data!H11/Raw_Stock_Data!H10)-1 -> -0.0019052942 | I11: =(Raw_Stock_Data!I11/Raw_Stock_Data!I10)-1 -> 0.02328611 | J11: =(Raw_Stock_Data!J11/Raw_Stock_Data!J10)-1 -> -0.0087045782
A12: 44215 | B12: =(Raw_Stock_Data!B12/Raw_Stock_Data!B11)-1 -> 0.0053976309 | C12: =(Raw_Stock_Data!C12/Raw_Stock_Data!C11)-1 -> 0.017859836 | D12: =(Raw_Stock_Data!D12/Raw_Stock_Data!D11)-1 -> 0.012926061 | E12: =(Raw_Stock_Data!E12/Raw_Stock_Data!E11)-1 -> 0.014057363 | F12: =(Raw_Stock_Data!F12/Raw_Stock_Data!F11)-1 -> 0.0053217535 | G12: =(Raw_Stock_Data!G12/Raw_Stock_Data!G11)-1 -> 0.022259584 | H12: =(Raw_Stock_Data!H12/Raw_Stock_Data!H11)-1 -> 0.032904957 | I12: =(Raw_Stock_Data!I12/Raw_Stock_Data!I11)-1 -> 0.038749204 | J12: =(Raw_Stock_Data!J12/Raw_Stock_Data!J11)-1 -> 0.015284841
A13: 44216 | B13: =(Raw_Stock_Data!B13/Raw_Stock_Data!B12)-1 -> 0.032919165 | C13: =(Raw_Stock_Data!C13/Raw_Stock_Data!C12)-1 -> 0.036416909 | D13: =(Raw_Stock_Data!D13/Raw_Stock_Data!D12)-1 -> 0.026130259 | E13: =(Raw_Stock_Data!E13/Raw_Stock_Data!E12)-1 -> -0.0078256009 | F13: =(Raw_Stock_Data!F13/Raw_Stock_Data!F12)-1 -> 0.045700406 | G13: =(Raw_Stock_Data!G13/Raw_Stock_Data!G12)-1 -> 0.0069835925 | H13: =(Raw_Stock_Data!H13/Raw_Stock_Data!H12)-1 -> 0.05357408 | I13: =(Raw_Stock_Data!I13/Raw_Stock_Data!I12)-1 -> 0.024435082 | J13: =(Raw_Stock_Data!J13/Raw_Stock_Data!J12)-1 -> 0.019706483
A14: 44217 | B14: =(Raw_Stock_Data!B14/Raw_Stock_Data!B13)-1 -> 0.036779695 | C14: =(Raw_Stock_Data!C14/Raw_Stock_Data!C13)-1 -> 0.0028408698 | D14: =(Raw_Stock_Data!D14/Raw_Stock_Data!D13)-1 -> 0.037608479 | E14: =(Raw_Stock_Data!E14/Raw_Stock_Data!E13)-1 -> 0.031323944 | F14: =(Raw_Stock_Data!F14/Raw_Stock_Data!F13)-1 -> 0.013360381 | G14: =(Raw_Stock_Data!G14/Raw_Stock_Data!G13)-1 -> -0.0064201381 | H14: =(Raw_Stock_Data!H14/Raw_Stock_Data!H13)-1 -> 0.0021694568 | I14: =(Raw_Stock_Data!I14/Raw_Stock_Data!I13)-1 -> 0.020151039 | J14: =(Raw_Stock_Data!J14/Raw_Stock_Data!J13)-1 -> 0.0054743726
... A1256: 46022 | B1256: =(Raw_Stock_Data!B1256/Raw_Stock_Data!B1255)-1 -> -0.0044675553 | C1256: =(Raw_Stock_Data!C1256/Raw_Stock_Data!C1255)-1 -> -0.0079182736 | D1256: =(Raw_Stock_Data!D1256/Raw_Stock_Data!D1255)-1 -> -0.0055454836 | E1256: =(Raw_Stock_Data!E1256/Raw_Stock_Data!E1255)-1 -> -0.0054797065 | F1256: =(Raw_Stock_Data!F1256/Raw_Stock_Data!F1255)-1 -> -0.0073538898 | G1256: =(Raw_Stock_Data!G1256/Raw_Stock_Data!G1255)-1 -> -0.010364633 | H1256: =(Raw_Stock_Data!H1256/Raw_Stock_Data!H1255)-1 -> -0.0027083001 | I1256: =(Raw_Stock_Data!I1256/Raw_Stock_Data!I1255)-1 -> -0.0087994594 | J1256: =(Raw_Stock_Data!J1256/Raw_Stock_Data!J1255)-1 -> -0.007561783

Sheet Summary_sheet
A1: Stock/Indicies | B1: Avg Daily Return | C1: Annual Return | D1: Volatility | E1: Sharpe
A2: AAPL | B2: =AVERAGE(Daily_returns_cal!B3:B1256) -> 0.00076674074 | C2: =(1+B2)^252-1 -> 0.21305823 | D2: =_xlfn.STDEV.P(Daily_returns_cal!B3:B1256)*SQRT(252) -> 0.2785147 | E2: =(C2-Risk_free_rate!$B$1)/Summary_sheet!D2 -> 0.61346214
A3: MSFT | B3: =AVERAGE(Daily_returns_cal!C3:C1256) -> 0.00079462434 | C3: =(1+B3)^252-1 -> 0.2216053 | D3: =_xlfn.STDEV.P(Daily_returns_cal!C3:C1256)*SQRT(252) -> 0.25705455 | E3: =(C3-Risk_free_rate!$B$1)/Summary_sheet!D3 -> 0.69792696
A4: NVDA | B4: =AVERAGE(Daily_returns_cal!D3:D1256) -> 0.0026564861 | C4: =(1+B4)^252-1 -> 0.95139967 | D4: =_xlfn.STDEV.P(Daily_returns_cal!D3:D1256)*SQRT(252) -> 0.522031 | E4: =(C4-Risk_free_rate!$B$1)/Summary_sheet!D4 -> 1.7416584
A5: AMD | B5: =AVERAGE(Daily_returns_cal!E3:E1256) -> 0.0012097415 | C5: =(1+B5)^252-1 -> 0.35617822 | D5: =_xlfn.STDEV.P(Daily_returns_cal!E3:E1256)*SQRT(252) -> 0.52384239 | E5: =(C5-Risk_free_rate!$B$1)/Summary_sheet!D5 -> 0.59937536
A6: AMZN | B6: =AVERAGE(Daily_returns_cal!F3:F1256) -> 0.00053975534 | C6: =(1+B6)^252-1 -> 0.14566087 | D6: =_xlfn.STDEV.P(Daily_returns_cal!F3:F1256)*SQRT(252) -> 0.35091971 | E6: =(C6-Risk_free_rate!$B$1)/Summary_sheet!D6 -> 0.29482775
A7: TSLA | B7: =AVERAGE(Daily_returns_cal!G3:G1256) -> 0.0012166811 | C7: =(1+B7)^252-1 -> 0.35854908 | D7: =_xlfn.STDEV.P(Daily_returns_cal!G3:G1256)*SQRT(252) -> 0.60711574 | E7: =(C7-Risk_free_rate!$B$1)/Summary_sheet!D7 -> 0.52106881
A8: GOOGL | B8: =AVERAGE(Daily_returns_cal!H3:H1256) -> 0.0012228511 | C8: =(1+B8)^252-1 -> 0.36066047 | D8: =_xlfn.STDEV.P(Daily_returns_cal!H3:H1256)*SQRT(252) -> 0.31136883 | E8: =(C8-Risk_free_rate!$B$1)/Summary_sheet!D8 -> 1.0227757
A9: META | B9: =AVERAGE(Daily_returns_cal!I3:I1256) -> 0.0010943113 | C9: =(1+B9)^252-1 -> 0.31734149 | D9: =_xlfn.STDEV.P(Daily_returns_cal!I3:I1256)*SQRT(252) -> 0.43393879 | E9: =(C9-Risk_free_rate!$B$1)/Summary_sheet!D9 -> 0.63405599
A10: Nasdaq | B10: =AVERAGE(Daily_returns_cal!J3:J1256) -> 0.00058393859 | C10: =(1+B10)^252-1 -> 0.1584809 | D10: =_xlfn.STDEV.P(Daily_returns_cal!J3:J1256)*SQRT(252) -> 0.22667215 | E10: =(C10-Risk_free_rate!$B$1)/Summary_sheet!D10 -> 0.51299156
A13: Stock/Indicies | B13: Investment | C13: Weights
A14: AAPL | B14: 200000 | C14: =B14/$B$22 -> 0.083333333
A15: MSFT | B15: 300000 | C15: =B15/$B$22 -> 0.125
A16: NVDA | B16: 500000 | C16: =B16/$B$22 -> 0.20833333
A17: AMD | B17: 100000 | C17: =B17/$B$22 -> 0.041666667
A18: AMZN | B18: 600000 | C18: =B18/$B$22 -> 0.25
A19: TSLA | B19: 300000 | C19: =B19/$B$22 -> 0.125
A20: GOOGL | B20: 150000 | C20: =B20/$B$22 -> 0.0625
A21: META | B21: 250000 | C21: =B21/$B$22 -> 0.10416667
A22: Total | B22: =SUM(B14:B21) -> 2400000 | C22: =SUM(C14:C21) -> 1
A24: Correlation | B24: AAPL | C24: MSFT | D24: NVDA | E24: AMD | F24: AMZN | G24: TSLA | H24: GOOGL | I24: META
A25: AAPL | B25: =CORREL(Daily_returns_cal!B3:B1256,Daily_returns_cal!B3:B1256) -> 1 | C25: =CORREL(Daily_returns_cal!$B$3:$B$1256,Daily_returns_cal!C3:C1256) -> 0.63395545 | D25: =CORREL(Daily_returns_cal!$B$3:$B$1256,Daily_returns_cal!D3:D1256) -> 0.51989039 | E25: =CORREL(Daily_returns_cal!$B$3:$B$1256,Daily_returns_cal!E3:E1256) -> 0.50525533 | F25: =CORREL(Daily_returns_cal!$B$3:$B$1256,Daily_returns_cal!F3:F1256) -> 0.56131828 | G25: =CORREL(Daily_returns_cal!$B$3:$B$1256,Daily_returns_cal!G3:G1256) -> 0.50019598 | H25: =CORREL(Daily_returns_cal!$B$3:$B$1256,Daily_returns_cal!H3:H1256) -> 0.57871273 | I25: =CORREL(Daily_returns_cal!$B$3:$B$1256,Daily_returns_cal!I3:I1256) -> 0.48886364
A26: MSFT | B26: =CORREL(Daily_returns_cal!$C$3:$C$1256,Daily_returns_cal!B3:B1256) -> 0.63395545 | C26: =CORREL(Daily_returns_cal!$C$3:$C$1256,Daily_returns_cal!C3:C1256) -> 1 | D26: =CORREL(Daily_returns_cal!$C$3:$C$1256,Daily_returns_cal!D3:D1256) -> 0.63048097 | E26: =CORREL(Daily_returns_cal!$C$3:$C$1256,Daily_returns_cal!E3:E1256) -> 0.55846978 | F26: =CORREL(Daily_returns_cal!$C$3:$C$1256,Daily_returns_cal!F3:F1256) -> 0.65496647 | G26: =CORREL(Daily_returns_cal!$C$3:$C$1256,Daily_returns_cal!G3:G1256) -> 0.42346022 | H26: =CORREL(Daily_returns_cal!$C$3:$C$1256,Daily_returns_cal!H3:H1256) -> 0.64429033 | I26: =CORREL(Daily_returns_cal!$C$3:$C$1256,Daily_returns_cal!I3:I1256) -> 0.5920945
A27: NVDA | B27: =CORREL(Daily_returns_cal!$D$3:$D$1256,Daily_returns_cal!B3:B1256) -> 0.51989039 | C27: =CORREL(Daily_returns_cal!$D$3:$D$1256,Daily_returns_cal!C3:C1256) -> 0.63048097 | D27: =CORREL(Daily_returns_cal!$D$3:$D$1256,Daily_returns_cal!D3:D1256) -> 1 | E27: =CORREL(Daily_returns_cal!$D$3:$D$1256,Daily_returns_cal!E3:E1256) -> 0.70040219 | F27: =CORREL(Daily_returns_cal!$D$3:$D$1256,Daily_returns_cal!F3:F1256) -> 0.55717267 | G27: =CORREL(Daily_returns_cal!$D$3:$D$1256,Daily_returns_cal!G3:G1256) -> 0.46781873 | H27: =CORREL(Daily_returns_cal!$D$3:$D$1256,Daily_returns_cal!H3:H1256) -> 0.52756128 | I27: =CORREL(Daily_returns_cal!$D$3:$D$1256,Daily_returns_cal!I3:I1256) -> 0.49826458
A28: AMD | B28: =CORREL(Daily_returns_cal!$E$3:$E$1256,Daily_returns_cal!B3:B1256) -> 0.50525533 | C28: =CORREL(Daily_returns_cal!$E$3:$E$1256,Daily_returns_cal!C3:C1256) -> 0.55846978 | D28: =CORREL(Daily_returns_cal!$E$3:$E$1256,Daily_returns_cal!D3:D1256) -> 0.70040219 | E28: =CORREL(Daily_returns_cal!$E$3:$E$1256,Daily_returns_cal!E3:E1256) -> 1 | F28: =CORREL(Daily_returns_cal!$E$3:$E$1256,Daily_returns_cal!F3:F1256) -> 0.51984563 | G28: =CORREL(Daily_returns_cal!$E$3:$E$1256,Daily_returns_cal!G3:G1256) -> 0.45667956 | H28: =CORREL(Daily_returns_cal!$E$3:$E$1256,Daily_returns_cal!H3:H1256) -> 0.51677586 | I28: =CORREL(Daily_returns_cal!$E$3:$E$1256,Daily_returns_cal!I3:I1256) -> 0.47058247
A29: AMZN | B29: =CORREL(Daily_returns_cal!$F$3:$F$1256,Daily_returns_cal!B3:B1256) -> 0.56131828 | C29: =CORREL(Daily_returns_cal!$F$3:$F$1256,Daily_returns_cal!C3:C1256) -> 0.65496647 | D29: =CORREL(Daily_returns_cal!$F$3:$F$1256,Daily_returns_cal!D3:D1256) -> 0.55717267 | E29: =CORREL(Daily_returns_cal!$F$3:$F$1256,Daily_returns_cal!E3:E1256) -> 0.51984563 | F29: =CORREL(Daily_returns_cal!$F$3:$F$1256,Daily_returns_cal!F3:F1256) -> 1 | G29: =CORREL(Daily_returns_cal!$F$3:$F$1256,Daily_returns_cal!G3:G1256) -> 0.44864242 | H29: =CORREL(Daily_returns_cal!$F$3:$F$1256,Daily_returns_cal!H3:H1256) -> 0.61918336 | I29: =CORREL(Daily_returns_cal!$F$3:$F$1256,Daily_returns_cal!I3:I1256) -> 0.60101589
A30: TSLA | B30: =CORREL(Daily_returns_cal!$G$3:$G$1256,Daily_returns_cal!B3:B1256) -> 0.50019598 | C30: =CORREL(Daily_returns_cal!$G$3:$G$1256,Daily_returns_cal!C3:C1256) -> 0.42346022 | D30: =CORREL(Daily_returns_cal!$G$3:$G$1256,Daily_returns_cal!D3:D1256) -> 0.46781873 | E30: =CORREL(Daily_returns_cal!$G$3:$G$1256,Daily_returns_cal!E3:E1256) -> 0.45667956 | F30: =CORREL(Daily_returns_cal!$G$3:$G$1256,Daily_returns_cal!F3:F1256) -> 0.44864242 | G30: =CORREL(Daily_returns_cal!$G$3:$G$1256,Daily_returns_cal!G3:G1256) -> 1 | H30: =CORREL(Daily_returns_cal!$G$3:$G$1256,Daily_returns_cal!H3:H1256) -> 0.41659499 | I30: =CORREL(Daily_returns_cal!$G$3:$G$1256,Daily_returns_cal!I3:I1256) -> 0.34766095
A31: GOOGL | B31: =CORREL(Daily_returns_cal!$H$3:$H$1256,Daily_returns_cal!B3:B1256) -> 0.57871273 | C31: =CORREL(Daily_returns_cal!$H$3:$H$1256,Daily_returns_cal!C3:C1256) -> 0.64429033 | D31: =CORREL(Daily_returns_cal!$H$3:$H$1256,Daily_returns_cal!D3:D1256) -> 0.52756128 | E31: =CORREL(Daily_returns_cal!$H$3:$H$1256,Daily_returns_cal!E3:E1256) -> 0.51677586 | F31: =CORREL(Daily_returns_cal!$H$3:$H$1256,Daily_returns_cal!F3:F1256) -> 0.61918336 | G31: =CORREL(Daily_returns_cal!$H$3:$H$1256,Daily_returns_cal!G3:G1256) -> 0.41659499 | H31: =CORREL(Daily_returns_cal!$H$3:$H$1256,Daily_returns_cal!H3:H1256) -> 1 | I31: =CORREL(Daily_returns_cal!$H$3:$H$1256,Daily_returns_cal!I3:I1256) -> 0.56355465
A32: META | B32: =CORREL(Daily_returns_cal!$I$3:$I$1256,Daily_returns_cal!B3:B1256) -> 0.48886364 | C32: =CORREL(Daily_returns_cal!$I$3:$I$1256,Daily_returns_cal!C3:C1256) -> 0.5920945 | D32: =CORREL(Daily_returns_cal!$I$3:$I$1256,Daily_returns_cal!D3:D1256) -> 0.49826458 | E32: =CORREL(Daily_returns_cal!$I$3:$I$1256,Daily_returns_cal!E3:E1256) -> 0.47058247 | F32: =CORREL(Daily_returns_cal!$I$3:$I$1256,Daily_returns_cal!F3:F1256) -> 0.60101589 | G32: =CORREL(Daily_returns_cal!$I$3:$I$1256,Daily_returns_cal!G3:G1256) -> 0.34766095 | H32: =CORREL(Daily_returns_cal!$I$3:$I$1256,Daily_returns_cal!H3:H1256) -> 0.56355465 | I32: =CORREL(Daily_returns_cal!$I$3:$I$1256,Daily_returns_cal!I3:I1256) -> 1
A34: Co-variance | B34: AAPL | C34: MSFT | D34: NVDA | E34: AMD | F34: AMZN | G34: TSLA | H34: GOOGL | I34: META
A35: AAPL | B35: =_xlfn.COVARIANCE.P(Daily_returns_cal!$B$3:$B$1256,Daily_returns_cal!B3:B1256) -> 0.00030781921 | C35: =_xlfn.COVARIANCE.P(Daily_returns_cal!$B$3:$B$1256,Daily_returns_cal!C3:C1256) -> 0.00018010743 | D35: =_xlfn.COVARIANCE.P(Daily_returns_cal!$B$3:$B$1256,Daily_returns_cal!D3:D1256) -> 0.0002999547 | E35: =_xlfn.COVARIANCE.P(Daily_returns_cal!$B$3:$B$1256,Daily_returns_cal!E3:E1256) -> 0.0002925224 | F35: =_xlfn.COVARIANCE.P(Daily_returns_cal!$B$3:$B$1256,Daily_returns_cal!F3:F1256) -> 0.00021770307 | G35: =_xlfn.COVARIANCE.P(Daily_returns_cal!$B$3:$B$1256,Daily_returns_cal!G3:G1256) -> 0.00033562884 | H35: =_xlfn.COVARIANCE.P(Daily_returns_cal!$B$3:$B$1256,Daily_returns_cal!H3:H1256) -> 0.0001991525 | I35: =_xlfn.COVARIANCE.P(Daily_returns_cal!$B$3:$B$1256,Daily_returns_cal!I3:I1256) -> 0.00023445732
A36: MSFT | B36: =_xlfn.COVARIANCE.P(Daily_returns_cal!$C$3:$C$1256,Daily_returns_cal!B3:B1256) -> 0.00018010743 | C36: =_xlfn.COVARIANCE.P(Daily_returns_cal!$C$3:$C$1256,Daily_returns_cal!C3:C1256) -> 0.00026221048 | D36: =_xlfn.COVARIANCE.P(Daily_returns_cal!$C$3:$C$1256,Daily_returns_cal!D3:D1256) -> 0.00033573223 | E36: =_xlfn.COVARIANCE.P(Daily_returns_cal!$C$3:$C$1256,Daily_returns_cal!E3:E1256) -> 0.00029841804 | F36: =_xlfn.COVARIANCE.P(Daily_returns_cal!$C$3:$C$1256,Daily_returns_cal!F3:F1256) -> 0.00023445073 | G36: =_xlfn.COVARIANCE.P(Daily_returns_cal!$C$3:$C$1256,Daily_returns_cal!G3:G1256) -> 0.000262246 | H36: =_xlfn.COVARIANCE.P(Daily_returns_cal!$C$3:$C$1256,Daily_returns_cal!H3:H1256) -> 0.00020463575 | I36: =_xlfn.COVARIANCE.P(Daily_returns_cal!$C$3:$C$1256,Daily_returns_cal!I3:I1256) -> 0.00026208626
A37: NVDA | B37: =_xlfn.COVARIANCE.P(Daily_returns_cal!$D$3:$D$1256,Daily_returns_cal!B3:B1256) -> 0.0002999547 | C37: =_xlfn.COVARIANCE.P(Daily_returns_cal!$D$3:$D$1256,Daily_returns_cal!C3:C1256) -> 0.00033573223 | D37: =_xlfn.COVARIANCE.P(Daily_returns_cal!$D$3:$D$1256,Daily_returns_cal!D3:D1256) -> 0.0010814142 | E37: =_xlfn.COVARIANCE.P(Daily_returns_cal!$D$3:$D$1256,Daily_returns_cal!E3:E1256) -> 0.00076005303 | F37: =_xlfn.COVARIANCE.P(Daily_returns_cal!$D$3:$D$1256,Daily_returns_cal!F3:F1256) -> 0.00040503572 | G37: =_xlfn.COVARIANCE.P(Daily_returns_cal!$D$3:$D$1256,Daily_returns_cal!G3:G1256) -> 0.00058836232 | H37: =_xlfn.COVARIANCE.P(Daily_returns_cal!$D$3:$D$1256,Daily_returns_cal!H3:H1256) -> 0.00034028578 | I37: =_xlfn.COVARIANCE.P(Daily_returns_cal!$D$3:$D$1256,Daily_returns_cal!I3:I1256) -> 0.00044790328
A38: AMD | B38: =_xlfn.COVARIANCE.P(Daily_returns_cal!$E$3:$E$1256,Daily_returns_cal!B3:B1256) -> 0.0002925224 | C38: =_xlfn.COVARIANCE.P(Daily_returns_cal!$E$3:$E$1256,Daily_returns_cal!C3:C1256) -> 0.00029841804 | D38: =_xlfn.COVARIANCE.P(Daily_returns_cal!$E$3:$E$1256,Daily_returns_cal!D3:D1256) -> 0.00076005303 | E38: =_xlfn.COVARIANCE.P(Daily_returns_cal!$E$3:$E$1256,Daily_returns_cal!E3:E1256) -> 0.0010889319 | F38: =_xlfn.COVARIANCE.P(Daily_returns_cal!$E$3:$E$1256,Daily_returns_cal!F3:F1256) -> 0.00037921217 | G38: =_xlfn.COVARIANCE.P(Daily_returns_cal!$E$3:$E$1256,Daily_returns_cal!G3:G1256) -> 0.00057634584 | H38: =_xlfn.COVARIANCE.P(Daily_returns_cal!$E$3:$E$1256,Daily_returns_cal!H3:H1256) -> 0.00033448562 | I38: =_xlfn.COVARIANCE.P(Daily_returns_cal!$E$3:$E$1256,Daily_returns_cal!I3:I1256) -> 0.00042448692
A39: AMZN | B39: =_xlfn.COVARIANCE.P(Daily_returns_cal!$F$3:$F$1256,Daily_returns_cal!B3:B1256) -> 0.00021770307 | C39: =_xlfn.COVARIANCE.P(Daily_returns_cal!$F$3:$F$1256,Daily_returns_cal!C3:C1256) -> 0.00023445073 | D39: =_xlfn.COVARIANCE.P(Daily_returns_cal!$F$3:$F$1256,Daily_returns_cal!D3:D1256) -> 0.00040503572 | E39: =_xlfn.COVARIANCE.P(Daily_returns_cal!$F$3:$F$1256,Daily_returns_cal!E3:E1256) -> 0.00037921217 | F39: =_xlfn.COVARIANCE.P(Daily_returns_cal!$F$3:$F$1256,Daily_returns_cal!F3:F1256) -> 0.00048866923 | G39: =_xlfn.COVARIANCE.P(Daily_returns_cal!$F$3:$F$1256,Daily_returns_cal!G3:G1256) -> 0.00037929669 | H39: =_xlfn.COVARIANCE.P(Daily_returns_cal!$F$3:$F$1256,Daily_returns_cal!H3:H1256) -> 0.00026847363 | I39: =_xlfn.COVARIANCE.P(Daily_returns_cal!$F$3:$F$1256,Daily_returns_cal!I3:I1256) -> 0.00036317977
A40: TSLA | B40: =_xlfn.COVARIANCE.P(Daily_returns_cal!$G$3:$G$1256,Daily_returns_cal!B3:B1256) -> 0.00033562884 | C40: =_xlfn.COVARIANCE.P(Daily_returns_cal!$G$3:$G$1256,Daily_returns_cal!C3:C1256) -> 0.000262246 | D40: =_xlfn.COVARIANCE.P(Daily_returns_cal!$G$3:$G$1256,Daily_returns_cal!D3:D1256) -> 0.00058836232 | E40: =_xlfn.COVARIANCE.P(Daily_returns_cal!$G$3:$G$1256,Daily_returns_cal!E3:E1256) -> 0.00057634584 | F40: =_xlfn.COVARIANCE.P(Daily_returns_cal!$G$3:$G$1256,Daily_returns_cal!F3:F1256) -> 0.00037929669 | G40: =_xlfn.COVARIANCE.P(Daily_returns_cal!$G$3:$G$1256,Daily_returns_cal!G3:G1256) -> 0.0014626568 | H40: =_xlfn.COVARIANCE.P(Daily_returns_cal!$G$3:$G$1256,Daily_returns_cal!H3:H1256) -> 0.00031250727 | I40: =_xlfn.COVARIANCE.P(Daily_returns_cal!$G$3:$G$1256,Daily_returns_cal!I3:I1256) -> 0.00036345892
A41: GOOGL | B41: =_xlfn.COVARIANCE.P(Daily_returns_cal!$H$3:$H$1256,Daily_returns_cal!B3:B1256) -> 0.0001991525 | C41: =_xlfn.COVARIANCE.P(Daily_returns_cal!$H$3:$H$1256,Daily_returns_cal!C3:C1256) -> 0.00020463575 | D41: =_xlfn.COVARIANCE.P(Daily_returns_cal!$H$3:$H$1256,Daily_returns_cal!D3:D1256) -> 0.00034028578 | E41: =_xlfn.COVARIANCE.P(Daily_returns_cal!$H$3:$H$1256,Daily_returns_cal!E3:E1256) -> 0.00033448562 | F41: =_xlfn.COVARIANCE.P(Daily_returns_cal!$H$3:$H$1256,Daily_returns_cal!F3:F1256) -> 0.00026847363 | G41: =_xlfn.COVARIANCE.P(Daily_returns_cal!$H$3:$H$1256,Daily_returns_cal!G3:G1256) -> 0.00031250727 | H41: =_xlfn.COVARIANCE.P(Daily_returns_cal!$H$3:$H$1256,Daily_returns_cal!H3:H1256) -> 0.0003847244 | I41: =_xlfn.COVARIANCE.P(Daily_returns_cal!$H$3:$H$1256,Daily_returns_cal!I3:I1256) -> 0.00030216148
A42: META | B42: =_xlfn.COVARIANCE.P(Daily_returns_cal!$I$3:$I$1256,Daily_returns_cal!B3:B1256) -> 0.00023445732 | C42: =_xlfn.COVARIANCE.P(Daily_returns_cal!$I$3:$I$1256,Daily_returns_cal!C3:C1256) -> 0.00026208626 | D42: =_xlfn.COVARIANCE.P(Daily_returns_cal!$I$3:$I$1256,Daily_returns_cal!D3:D1256) -> 0.00044790328 | E42: =_xlfn.COVARIANCE.P(Daily_returns_cal!$I$3:$I$1256,Daily_returns_cal!E3:E1256) -> 0.00042448692 | F42: =_xlfn.COVARIANCE.P(Daily_returns_cal!$I$3:$I$1256,Daily_returns_cal!F3:F1256) -> 0.00036317977 | G42: =_xlfn.COVARIANCE.P(Daily_returns_cal!$I$3:$I$1256,Daily_returns_cal!G3:G1256) -> 0.00036345892 | H42: =_xlfn.COVARIANCE.P(Daily_returns_cal!$I$3:$I$1256,Daily_returns_cal!H3:H1256) -> 0.00030216148 | I42: =_xlfn.COVARIANCE.P(Daily_returns_cal!$I$3:$I$1256,Daily_returns_cal!I3:I1256) -> 0.00074723361
A45: Return
A46: Portfolio | B46: =SUMPRODUCT(C14:C21,C2:C9) -> 0.39533607
...

Sheet Benchmark
B1: Portfolio | C1: Index
A2: Return | B2: =Summary_sheet!B46 -> 0.39533607 | C2: =Summary_sheet!B47 -> 0.1584809
A3: CAPM | B3: =Summary_sheet!$B$61 -> 0.20011856 | C3: =C2 -> 0.1584809
A4: Annual Risk | B4: =Summary_sheet!B53 -> 0.32256812 | C4: =Summary_sheet!B55 -> 0.22667215
A5: beta | B5: =Summary_sheet!B60 -> 1.3580782 | C5: 1
A6: Sharpe | B6: =(Summary_sheet!B46-Risk_free_rate!B1)/Summary_sheet!B53 -> 1.0947643 | C6: =Summary_sheet!E10 -> 0.51299156

Sheet DashBoard
A1: Metric | B1: Portfolio | C1: Index
A2: Risk(%) | B2: 0.3226 | C2: 0.2267
A3: Historical Return(%) | B3: 0.3953 | C3: 0.1585
A21: Metric | B21: Portfolio | C21: Index
A22: Historical return(%) | B22: =Benchmark!B2 -> 0.39533607 | C22: =Benchmark!C2 -> 0.1584809
A23: CAPM Return(%) | B23: =Benchmark!B3 -> 0.20011856 | C23: =Benchmark!C3 -> 0.1584809
A41: Asset | B41: Annual Risk (%)
A42: Portfolio | B42: =Benchmark!B4 -> 0.32256812
A43: Index | B43: =Benchmark!C4 -> 0.22667215
A60: Asset | B60: Sharpe Ratio
A61: Portfolio | B61: =Benchmark!B6 -> 1.0947643
A62: Index | B62: =Benchmark!C6 -> 0.51299156
A81: Portfolio mix | B81: Weights
A82: AAPL | B82: 0.083333333
A83: MSFT | B83: 0.125
A84: NVDA | B84: 0.20833333
A85: AMD | B85: 0.041666667
A86: AMZN | B86: 0.25
A87: TSLA | B87: 0.125
A88: GOOGL | B88: 0.0625
A89: META | B89: 0.10416667
A90: Total | B90: 1

Sheet F.Dashboard
A1: NASDAQ Portfolio Performance Dashboard
