Workbook

Sheet Income Statment (Trend)
B1: Income statement
B4: $ in millions | C4: 2021 | D4: 2022 | E4: 2023 | F4: 2024 | G4: 2025 | I4: Var % 2021-2022 | J4: Var % 2022-2023 | K4: Var % 2023-2024 | L4: Var % 2024-2025
B5: Net Sales | C5: 76118 | D5: 80187 | E5: 82006 | F5: 84039 | G5: 84284 | I5: =D5/C5-1 -> 0.053456475 | J5: =E5/D5-1 -> 0.022684475 | K5: =F5/E5-1 -> 0.024790869 | L5: =G5/F5-1 -> 0.0029153131
B6: Cost of products sold | C6: -37108 | D6: -42157 | E6: -42760 | F6: -40848 | G6: -41164 | I6: =D6/C6-1 -> 0.1360623 | J6: =E6/D6-1 -> 0.014303674 | K6: =F6/E6-1 -> -0.044714687 | L6: =G6/F6-1 -> 0.0077359969
B7: Gross Profit | C7: =SUM(C5:C6) -> 39010 | D7: =SUM(D5:D6) -> 38030 | E7: =SUM(E5:E6) -> 39246 | F7: =SUM(F5:F6) -> 43191 | G7: =SUM(G5:G6) -> 43120 | I7: =D7/C7-1 -> -0.025121764 | J7: =E7/D7-1 -> 0.031974757 | K7: =F7/E7-1 -> 0.1005198 | L7: =G7/F7-1 -> -0.001643861
B8: Selling, general and administrative expense | C8: -21024 | D8: -20217 | E8: -21112 | F8: -23305 | G8: -22669 | I8: =D8/C8-1 -> -0.038384703 | J8: =E8/D8-1 -> 0.044269674 | K8: =F8/E8-1 -> 0.10387457 | L8: =G8/F8-1 -> -0.027290281
B9: Indefinite-lived intangible asset impairment charge | C9: 0 | D9: 0 | E9: 0 | F9: 1341 | G9: 0 | I9: 0 | J9: 0 | K9: 0 | L9: =G9/F9-1 -> -1
B10: EBIT | C10: =SUM(C7:C9) -> 17986 | D10: 17813 | E10: 18134 | F10: 18545 | G10: 20451 | I10: =D10/C10-1 -> -0.0096185922 | J10: =E10/D10-1 -> 0.018020547 | K10: =F10/E10-1 -> 0.022664608 | L10: =G10/F10-1 -> 0.10277703
B11: Interest expense | C11: -502 | D11: -439 | E11: -756 | F11: -925 | G11: -907 | I11: =D11/C11-1 -> -0.12549801 | J11: =E11/D11-1 -> 0.72209567 | K11: =F11/E11-1 -> 0.22354497 | L11: =G11/F11-1 -> -0.019459459
B12: Interest income | C12: 45 | D12: 51 | E12: 307 | F12: 473 | G12: 469 | I12: =D12/C12-1 -> 0.13333333 | J12: =E12/D12-1 -> 5.0196078 | K12: =F12/E12-1 -> 0.54071661 | L12: =G12/F12-1 -> -0.0084566596
B13: Other non-operating income, net | C13: 86 | D13: 570 | E13: 668 | F13: 668 | G13: 154 | I13: =D13/C13-1 -> 5.627907 | J13: =E13/D13-1 -> 0.17192982 | K13: =F13/E13-1 -> 0 | L13: =G13/F13-1 -> -0.76946108
B14: EBT | C14: =SUM(C10:C13) -> 17615 | D14: =SUM(D10:D13) -> 17995 | E14: =SUM(E10:E13) -> 18353 | F14: =SUM(F10:F13) -> 18761 | G14: =SUM(G10:G13) -> 20167 | I14: =D14/C14-1 -> 0.021572523 | J14: =E14/D14-1 -> 0.019894415 | K14: =F14/E14-1 -> 0.022230698 | L14: =G14/F14-1 -> 0.0749427
B15: Income taxes | C15: -3263 | D15: -3202 | E15: -3615 | F15: -3787 | G15: -4102 | I15: =D15/C15-1 -> -0.018694453 | J15: =E15/D15-1 -> 0.12898189 | K15: =F15/E15-1 -> 0.04757953 | L15: =G15/F15-1 -> 0.083179298
B16: Net Earnings | C16: =SUM(C14:C15) -> 14352 | D16: =SUM(D14:D15) -> 14793 | E16: =SUM(E14:E15) -> 14738 | F16: =SUM(F14:F15) -> 14974 | G16: =SUM(G14:G15) -> 16065 | I16: =D16/C16-1 -> 0.030727425 | J16: =E16/D16-1 -> -0.0037179747 | K16: =F16/E16-1 -> 0.016013028 | L16: =G16/F16-1 -> 0.072859623
B17: Less: Net earnings attributable to noncontrolling interests | C17: -46 | D17: -51 | E17: -85 | F17: -95 | G17: -91 | I17: =D17/C17-1 -> 0.10869565 | J17: =E17/D17-1 -> 0.66666667 | K17: =F17/E17-1 -> 0.11764706 | L17: =G17/F17-1 -> -0.042105263
B18: Net Earnings Attributable to Procter & Gamble | C18: =SUM(C16:C17) -> 14306 | D18: =SUM(D16:D17) -> 14742 | E18: =SUM(E16:E17) -> 14653 | F18: =SUM(F16:F17) -> 14879 | G18: =SUM(G16:G17) -> 15974 | I18: =D18/C18-1 -> 0.030476723 | J18: =E18/D18-1 -> -0.0060371727 | K18: =F18/E18-1 -> 0.015423463 | L18: =G18/F18-1 -> 0.073593655
B19: Prefence Dividends | C19: 271 | D19: 281 | E19: 282 | F19: 284 | G19: 291
B20: Net Eanrnings to Common share holders | C20: =C18-C19 -> 14035 | D20: =D18-D19 -> 14461 | E20: =E18-E19 -> 14371 | F20: =F18-F19 -> 14595 | G20: =G18-G19 -> 15683
B22: Note
B23: Tax rate | C23: 0.185 | D23: 0.178 | E23: 0.197 | F23: 0.202 | G23: 0.203

Sheet Income Statment (Common Size)
B1: Income statement
B4: $ in millions | C4: 2021 | E4: 2022 | G4: 2023 | I4: 2024 | K4: 2025
B5: Net Sales | C5: 76118 | D5: =C5/C5 -> 1 | E5: 80187 | F5: =E5/E5 -> 1 | G5: 82006 | H5: =G5/G5 -> 1 | I5: 84039 | J5: =I5/I5 -> 1 | K5: 84284 | L5: =K5/K5 -> 1
B6: Cost of products sold | C6: -37108 | D6: =-C6/C$5 -> 0.48750624 | E6: -42157 | F6: =-E6/E$5 -> 0.5257336 | G6: -42760 | H6: =-G6/G$5 -> 0.52142526 | I6: -40848 | J6: =-I6/I$5 -> 0.48606004 | K6: -41164 | L6: =-K6/K$5 -> 0.48839637
B7: Gross Profit | C7: =SUM(C5:C6) -> 39010 | D7: =C7/C$5 -> 0.51249376 | E7: =SUM(E5:E6) -> 38030 | F7: =E7/E$5 -> 0.4742664 | G7: =SUM(G5:G6) -> 39246 | H7: =G7/G$5 -> 0.47857474 | I7: =SUM(I5:I6) -> 43191 | J7: =I7/I$5 -> 0.51393996 | K7: =SUM(K5:K6) -> 43120 | L7: =K7/K$5 -> 0.51160363
B8: Selling, general and administrative expense | C8: -21024 | D8: =-C8/C$5 -> 0.27620274 | E8: -20217 | F8: =-E8/E$5 -> 0.25212316 | G8: -21112 | H8: =-G8/G$5 -> 0.25744458 | I8: -23305 | J8: =-I8/I$5 -> 0.27731172 | K8: -22669 | L8: =-K8/K$5 -> 0.26895971
B9: Indefinite-lived intangible asset impairment charge | C9: 0 | D9: 0 | E9: 0 | F9: 0 | G9: 0 | H9: 0 | I9: 1341 | J9: =I9/I5 -> 0.015956877 | K9: 0 | L9: =K9/K5 -> 0
B10: EBIT | C10: =SUM(C7:C9) -> 17986 | D10: =C10/C$5 -> 0.23629102 | E10: 17813 | F10: =E10/E$5 -> 0.22214324 | G10: 18134 | H10: =G10/G$5 -> 0.22113016 | I10: 18545 | J10: =I10/I$5 -> 0.22067135 | K10: 20451 | L10: =K10/K$5 -> 0.24264392
B11: Interest expense | C11: -502 | D11: =-C11/C$5 -> 0.0065950235 | E11: -439 | F11: =-E11/E$5 -> 0.0054747029 | G11: -756 | H11: =-G11/G$5 -> 0.0092188376 | I11: -925 | J11: =-I11/I$5 -> 0.011006794 | K11: -907 | L11: =-K11/K$5 -> 0.010761236
B12: Interest income | C12: 45 | D12: =C12/C$5 -> 0.00059118737 | E12: 51 | F12: =E12/E$5 -> 0.00063601332 | G12: 307 | H12: =G12/G$5 -> 0.0037436285 | I12: 473 | J12: =I12/I$5 -> 0.0056283392 | K12: 469 | L12: =K12/K$5 -> 0.00556452
B13: Other non-operating income, net | C13: 86 | D13: =C13/C$5 -> 0.0011298247 | E13: 570 | F13: =E13/E$5 -> 0.0071083842 | G13: 668 | H13: =G13/G$5 -> 0.0081457454 | I13: 668 | J13: =I13/I$5 -> 0.0079486905 | K13: 154 | L13: =K13/K$5 -> 0.0018271558
B14: EBT | C14: =SUM(C10:C13) -> 17615 | D14: =C14/C$5 -> 0.23141701 | E14: =SUM(E10:E13) -> 17995 | F14: =E14/E$5 -> 0.22441293 | G14: =SUM(G10:G13) -> 18353 | H14: =G14/G$5 -> 0.2238007 | I14: =SUM(I10:I13) -> 18761 | J14: =I14/I$5 -> 0.22324159 | K14: =SUM(K10:K13) -> 20167 | L14: =K14/K$5 -> 0.23927436
B15: Income taxes | C15: -3263 | D15: =-C15/C$5 -> 0.042867653 | E15: -3202 | F15: =-E15/E$5 -> 0.03993166 | G15: -3615 | H15: =-G15/G$5 -> 0.04408214 | I15: -3787 | J15: =-I15/I$5 -> 0.045062411 | K15: -4102 | L15: =-K15/K$5 -> 0.048668786
B16: Net Earnings | C16: =SUM(C14:C15) -> 14352 | D16: =C16/C$5 -> 0.18854936 | E16: =SUM(E14:E15) -> 14793 | F16: =E16/E$5 -> 0.18448128 | G16: =SUM(G14:G15) -> 14738 | H16: =G16/G$5 -> 0.17971856 | I16: =SUM(I14:I15) -> 14974 | J16: =I16/I$5 -> 0.17817918 | K16: =SUM(K14:K15) -> 16065 | L16: =K16/K$5 -> 0.19060557
B17: Less: Net earnings attributable to noncontrolling interests | C17: -46 | D17: =-C17/C$5 -> 0.00060432486 | E17: -51 | F17: =-E17/E$5 -> 0.00063601332 | G17: -85 | H17: =-G17/G$5 -> 0.0010365095 | I17: -95 | J17: =-I17/I$5 -> 0.0011304275 | K17: -91 | L17: =-K17/K$5 -> 0.001079683
B18: Net Earnings Attributable to Procter & Gamble | C18: =SUM(C16:C17) -> 14306 | D18: =C18/C$5 -> 0.18794503 | E18: =SUM(E16:E17) -> 14742 | F18: =E18/E$5 -> 0.18384526 | G18: =SUM(G16:G17) -> 14653 | H18: =G18/G$5 -> 0.17868205 | I18: =SUM(I16:I17) -> 14879 | J18: =I18/I$5 -> 0.17704875 | K18: =SUM(K16:K17) -> 15974 | L18: =K18/K$5 -> 0.18952589
B20: KPIs | C20: 2021 | D20: 2022 | E20: 2023 | F20: 2024 | G20: 2025
B21: Gross Profit Margin | C21: =C7/C5 -> 0.51249376 | D21: =E7/E5 -> 0.4742664 | E21: =G7/G5 -> 0.47857474 | F21: =I7/I5 -> 0.51393996 | G21: =K7/K5 -> 0.51160363
B22: Operating Profit Margin | C22: =C10/C5 -> 0.23629102 | D22: =E10/E5 -> 0.22214324 | E22: =G10/G5 -> 0.22113016 | F22: =I10/I5 -> 0.22067135 | G22: =K10/K5 -> 0.24264392
B23: Net Profit Margin | C23: =C18/C5 -> 0.18794503 | D23: =E18/E5 -> 0.18384526 | E23: =G18/G5 -> 0.17868205 | F23: =I18/I5 -> 0.17704875 | G23: =K18/K5 -> 0.18952589

Sheet Balance Sheet (Trend)
B1: Balance Sheet
B4: $ in millions | C4: 44377 | D4: 44742 | E4: 45107 | F4: 45473 | G4: 45838 | H4: Var % 21-22 | I4: Var % 22-23 | J4: Var % 23-24 | K4: Var % 24-25
B5: Assets
B6: Current assets
B7: Cash and cash equivalents | C7: 10288 | D7: 7214 | E7: 8246 | F7: 9482 | G7: 9556 | H7: =D7/C7-1 -> -0.29879471 | I7: =E7/D7-1 -> 0.14305517 | J7: =F7/E7-1 -> 0.14989086 | K7: =G7/F7-1 -> 0.0078042607
B8: Accounts receivable | C8: 4725 | D8: 5143 | E8: 5471 | F8: 6118 | G8: 6185 | H8: =D8/C8-1 -> 0.088465608 | I8: =E8/D8-1 -> 0.063776006 | J8: =F8/E8-1 -> 0.11825992 | K8: =G8/F8-1 -> 0.010951291
B9: Inventories
B10: Materials and supplies | C10: 1645 | D10: 2168 | E10: 1863 | F10: 1617 | G10: 2022 | H10: =D10/C10-1 -> 0.31793313 | I10: =E10/D10-1 -> -0.14068266 | J10: =F10/E10-1 -> -0.13204509 | K10: =G10/F10-1 -> 0.25046382
B11: Work in process | C11: 719 | D11: 856 | E11: 956 | F11: 929 | G11: 1012 | H11: =D11/C11-1 -> 0.19054242 | I11: =E11/D11-1 -> 0.11682243 | J11: =F11/E11-1 -> -0.028242678 | K11: =G11/F11-1 -> 0.08934338
B12: Finished goods | C12: 3619 | D12: 3900 | E12: 4254 | F12: 4470 | G12: 4516 | H12: =D12/C12-1 -> 0.077645758 | I12: =E12/D12-1 -> 0.090769231 | J12: =F12/E12-1 -> 0.05077574 | K12: =G12/F12-1 -> 0.010290828
B13: Total inventories | C13: 5983 | D13: 6924 | E13: 7073 | F13: 7016 | G13: 7551 | H13: =D13/C13-1 -> 0.15727896 | I13: =E13/D13-1 -> 0.021519353 | J13: =F13/E13-1 -> -0.0080588152 | K13: =G13/F13-1 -> 0.076254276
B14: Prepaid expenses and other current assets | C14: 2095 | D14: 2372 | E14: 1858 | F14: 2095 | G14: 2100 | H14: =D14/C14-1 -> 0.13221957 | I14: =E14/D14-1 -> -0.21669477 | J14: =F14/E14-1 -> 0.12755651 | K14: =G14/F14-1 -> 0.0023866348
B15: Total current assets | C15: 23091 | D15: 21653 | E15: 22648 | F15: 24709 | G15: 25392 | H15: =D15/C15-1 -> -0.062275345 | I15: =E15/D15-1 -> 0.045952062 | J15: =F15/E15-1 -> 0.091001413 | K15: =G15/F15-1 -> 0.02764175
B16: Property, plant and equipment, net | C16: 21686 | D16: 21195 | E16: 21909 | F16: 22152 | G16: 23897 | H16: =D16/C16-1 -> -0.022641335 | I16: =E16/D16-1 -> 0.03368719 | J16: =F16/E16-1 -> 0.011091332 | K16: =G16/F16-1 -> 0.078773926
B17: Goodwill | C17: 40924 | D17: 39700 | E17: 40659 | F17: 40303 | G17: 41650 | H17: =D17/C17-1 -> -0.0299091 | I17: =E17/D17-1 -> 0.024156171 | J17: =F17/E17-1 -> -0.008755749 | K17: =G17/F17-1 -> 0.03342183
B18: Trademarks and other intangible assets, net | C18: 23642 | D18: 23679 | E18: 23783 | F18: 22047 | G18: 21910 | H18: =D18/C18-1 -> 0.0015650114 | I18: =E18/D18-1 -> 0.0043920774 | J18: =F18/E18-1 -> -0.072993315 | K18: =G18/F18-1 -> -0.0062139974
B19: Other noncurrent assets | C19: 9964 | D19: 10981 | E19: 11830 | F19: 13158 | G19: 12381 | H19: =D19/C19-1 -> 0.10206744 | I19: =E19/D19-1 -> 0.077315363 | J19: =F19/E19-1 -> 0.11225697 | K19: =G19/F19-1 -> -0.059051528
B20: Total assets | C20: 119307 | D20: 117208 | E20: 120829 | F20: 122370 | G20: 125231 | H20: =D20/C20-1 -> -0.017593268 | I20: =E20/D20-1 -> 0.030893796 | J20: =F20/E20-1 -> 0.012753561 | K20: =G20/F20-1 -> 0.023379913
B22: Liabilities and shareholders' equity
B23: Current liabilities
B24: Accounts payable | C24: 13720 | D24: 14882 | E24: 14598 | F24: 15364 | G24: 15227 | H24: =D24/C24-1 -> 0.084693878 | I24: =E24/D24-1 -> -0.019083457 | J24: =F24/E24-1 -> 0.052472941 | K24: =G24/F24-1 -> -0.0089169487
B25: Accrued and other liabilities | C25: 10523 | D25: 9554 | E25: 10929 | F25: 11073 | G25: 11318 | H25: =D25/C25-1 -> -0.092084006 | I25: =E25/D25-1 -> 0.14391878 | J25: =F25/E25-1 -> 0.013175954 | K25: =G25/F25-1 -> 0.022125892
B26: Debt due within one year | C26: 8889 | D26: 8645 | E26: 10229 | F26: 7191 | G26: 9513 | H26: =D26/C26-1 -> -0.027449657 | I26: =E26/D26-1 -> 0.1832273 | J26: =F26/E26-1 -> -0.29699873 | K26: =G26/F26-1 -> 0.32290363
B27: Total current liabilities | C27: 33132 | D27: 33081 | E27: 35756 | F27: 33627 | G27: 36058 | H27: =D27/C27-1 -> -0.0015392974 | I27: =E27/D27-1 -> 0.080862126 | J27: =F27/E27-1 -> -0.059542454 | K27: =G27/F27-1 -> 0.072293098
B28: Long-term debt | C28: 23099 | D28: 22848 | E28: 24378 | F28: 25269 | G28: 24995 | H28: =D28/C28-1 -> -0.010866271 | I28: =E28/D28-1 -> 0.066964286 | J28: =F28/E28-1 -> 0.036549348 | K28: =G28/F28-1 -> -0.010843326
B29: Deferred income taxes | C29: 6153 | D29: 6809 | E29: 6478 | F29: 6516 | G29: 5774 | H29: =D29/C29-1 -> 0.10661466 | I29: =E29/D29-1 -> -0.048612131 | J29: =F29/E29-1 -> 0.005866008 | K29: =G29/F29-1 -> -0.11387354
B30: Other noncurrent liabilities | C30: 10269 | D30: 7616 | E30: 7152 | F30: 6398 | G30: 6120 | H30: =D30/C30-1 -> -0.25835037 | I30: =E30/D30-1 -> -0.06092437 | J30: =F30/E30-1 -> -0.10542506 | K30: =G30/F30-1 -> -0.043451078
B31: Total liabilities | C31: 72653 | D31: 70354 | E31: 73764 | F31: 71811 | G31: 72946 | H31: =D31/C31-1 -> -0.031643566 | I31: =E31/D31-1 -> 0.04846917 | J31: =F31/E31-1 -> -0.02647633 | K31: =G31/F31-1 -> 0.015805378
B34: Shareholders' equity
B35: Convertible class a preferred stock, stated value $1 per share (600
B36: Shares authorized) | C36: 870 | D36: 843 | E36: 819 | F36: 798 | G36: 777 | H36: =D36/C36-1 -> -0.031034483 | I36: =E36/D36-1 -> -0.028469751 | J36: =F36/E36-1 -> -0.025641026 | K36: =G36/F36-1 -> -0.026315789
B37: Non-voting class b preferred stock, stated value $1 per share (200
B38: Shares authorized) | C38: 0 | D38: 0 | E38: 0 | F38: 0 | G38: 0
B39: Common stock, stated value $1 per share (10,000 shares authorized;
B40: Shares issued: 2021 - 4,009.2, 2022 - 4,009.2, 2023 - 4,009.2, 2024 - 4,009.2, 2025 - 4,009.2) | C40: 4009 | D40: 4009 | E40: 4009 | F40: 4009 | G40: 4009 | H40: =D40/C40-1 -> 0 | I40: =E40/D40-1 -> 0 | J40: =F40/E40-1 -> 0 | K40: =G40/F40-1 -> 0
B41: Additional paid-in capital | C41: 64848 | D41: 65795 | E41: 66556 | F41: 67684 | G41: 68770 | H41: =D41/C41-1 -> 0.01460338 | I41: =E41/D41-1 -> 0.011566228 | J41: =F41/E41-1 -> 0.016948134 | K41: =G41/F41-1 -> 0.016045151
B42: Reserve for esop debt retirement | C42: -1006 | D42: -916 | E42: -821 | F42: -737 | G42: -672 | H42: =D42/C42-1 -> -0.089463221 | I42: =E42/D42-1 -> -0.10371179 | J42: =F42/E42-1 -> -0.10231425 | K42: =G42/F42-1 -> -0.088195387
B43: Accumulated other comprehensive loss | C43: -13744 | D43: -12189 | E43: -12220 | F43: -11900 | G43: -12143 | H43: =D43/C43-1 -> -0.11314028 | I43: =E43/D43-1 -> 0.0025432767 | J43: =F43/E43-1 -> -0.026186579 | K43: =G43/F43-1 -> 0.020420168
B44: Treasury stock, at cost (shares held: 2021 - 1,579.5, 2022 - 1,615.4, 2023 - 1,647.1, 2024 - 1,652.2; 2025 - 1,667.3) | C44: -114973 | D44: -123382 | E44: -129736 | F44: -133379 | G44: -138702 | H44: =D44/C44-1 -> 0.073138911 | I44: =E44/D44-1 -> 0.051498598 | J44: =F44/E44-1 -> 0.028080101 | K44: =G44/F44-1 -> 0.039908831
B45: Retained earnings | C45: 106374 | D45: 112429 | E45: 118170 | F45: 123811 | G45: 129973 | H45: =D45/C45-1 -> 0.056921804 | I45: =E45/D45-1 -> 0.051063338 | J45: =F45/E45-1 -> 0.047736312 | K45: =G45/F45-1 -> 0.049769407
...

Sheet Balance sheet (KPIs)
B1: Balance Sheet
B4: $ in millions | C4: 44377 | D4: 44742 | E4: 45107 | F4: 45473 | G4: 45838 | I4: KPIs | J4: 2021 | K4: 2022 | L4: 2023 | M4: 2024 | N4: 2025
B5: Assets | I5: Current Ratio | J5: =C15/C27 -> 0.69693951 | K5: =D15/D27 -> 0.6545449 | L5: =E15/E27 -> 0.63340418 | M5: =F15/F27 -> 0.73479644 | N5: =G15/G27 -> 0.70419879
B6: Current assets | I6: Quick Ratio | J6: =(C7+C8)/C27 -> 0.45312689 | K6: =(D7+D8)/D27 -> 0.37353768 | L6: =(E7+E8)/E27 -> 0.38362792 | M6: =(F7+F8)/F27 -> 0.46391293 | N6: =(G7+G8)/G27 -> 0.43654667
B7: Cash and cash equivalents | C7: 10288 | D7: 7214 | E7: 8246 | F7: 9482 | G7: 9556 | I7: Cash Ratio | J7: =C7/C27 -> 0.31051551 | K7: =D7/D27 -> 0.2180708 | L7: =E7/E27 -> 0.23061864 | M7: =F7/F27 -> 0.28197579 | N7: =G7/G27 -> 0.26501747
B8: Accounts receivable | C8: 4725 | D8: 5143 | E8: 5471 | F8: 6118 | G8: 6185 | I8: Working Capital | J8: =C15-C27 -> -10041 | K8: =D15-D27 -> -11428 | L8: =E15-E27 -> -13108 | M8: =F15-F27 -> -8918 | N8: =G15-G27 -> -10666
B9: Inventories
B10: Materials and supplies | C10: 1645 | D10: 2168 | E10: 1863 | F10: 1617 | G10: 2022 | I10: Debt to equity | J10: =C31/C47 -> 1.5572727 | K10: =D31/D47 -> 1.501558 | L10: =E31/E47 -> 1.5672793 | M10: =F31/F47 -> 1.4203406 | N10: =G31/G47 -> 1.3951878
B11: Work in process | C11: 719 | D11: 856 | E11: 956 | F11: 929 | G11: 1012 | I11: Debt to capital | J11: =(C31-(C24+C25))/C49 -> 0.40575993 | K11: =(D31-(D24+D25))/D49 -> 0.39176507 | L11: =(E31-(E24+E25))/E49 -> 0.39921708 | M11: =(F31-(F24+F25))/F49 -> 0.3707935 | N11: =(G31-(G24+G25))/G49 -> 0.37052327
B12: Finished goods | C12: 3619 | D12: 3900 | E12: 4254 | F12: 4470 | G12: 4516 | I12: Debt to Assets | J12: =C31/C20 -> 0.6089584 | K12: =D31/D20 -> 0.60024913 | L12: =E31/E20 -> 0.61048258 | M12: =F31/F20 -> 0.58683501 | N12: =G31/G20 -> 0.58249156
B13: Total inventories | C13: 5983 | D13: 6924 | E13: 7073 | F13: 7016 | G13: 7551 | I13: Financial Levarage | K13: =((C20+D20)/2)/((C47+D47)/2) -> 2.5293558 | L13: =((D20+E20)/2)/((D47+E47)/2) -> 2.5344925 | M13: =((E20+F20)/2)/((E47+F47)/2) -> 2.4911804 | N13: =((F20+G20)/2)/((F47+G47)/2) -> 2.407563
B14: Prepaid expenses and other current assets | C14: 2095 | D14: 2372 | E14: 1858 | F14: 2095 | G14: 2100
B15: Total current assets | C15: 23091 | D15: 21653 | E15: 22648 | F15: 24709 | G15: 25392
B16: Property, plant and equipment, net | C16: 21686 | D16: 21195 | E16: 21909 | F16: 22152 | G16: 23897
B17: Goodwill | C17: 40924 | D17: 39700 | E17: 40659 | F17: 40303 | G17: 41650
B18: Trademarks and other intangible assets, net | C18: 23642 | D18: 23679 | E18: 23783 | F18: 22047 | G18: 21910
B19: Other noncurrent assets | C19: 9964 | D19: 10981 | E19: 11830 | F19: 13158 | G19: 12381
B20: Total assets | C20: 119307 | D20: 117208 | E20: 120829 | F20: 122370 | G20: 125231
B22: Liabilities and shareholders' equity
B23: Current liabilities
B24: Accounts payable | C24: 13720 | D24: 14882 | E24: 14598 | F24: 15364 | G24: 15227
B25: Accrued and other liabilities | C25: 10523 | D25: 9554 | E25: 10929 | F25: 11073 | G25: 11318
B26: Debt due within one year | C26: 8889 | D26: 8645 | E26: 10229 | F26: 7191 | G26: 9513
B27: Total current liabilities | C27: 33132 | D27: 33081 | E27: 35756 | F27: 33627 | G27: 36058
B28: Long-term debt | C28: 23099 | D28: 22848 | E28: 24378 | F28: 25269 | G28: 24995
B29: Deferred income taxes | C29: 6153 | D29: 6809 | E29: 6478 | F29: 6516 | G29: 5774
B30: Other noncurrent liabilities | C30: 10269 | D30: 7616 | E30: 7152 | F30: 6398 | G30: 6120
B31: Total liabilities | C31: 72653 | D31: 70354 | E31: 73764 | F31: 71811 | G31: 72946
B34: Shareholders' equity
B35: Convertible class a preferred stock, stated value $1 per share (600
B36: Shares authorized) | C36: 870 | D36: 843 | E36: 819 | F36: 798 | G36: 777
B37: Non-voting class b preferred stock, stated value $1 per share (200
B38: Shares authorized) | C38: 0 | D38: 0 | E38: 0 | F38: 0 | G38: 0
B39: Common stock, stated value $1 per share (10,000 shares authorized;
B40: Shares issued: 2021 - 4,009.2, 2022 - 4,009.2, 2023 - 4,009.2, 2024 - 4,009.2, 2025 - 4,009.2) | C40: 4009 | D40: 4009 | E40: 4009 | F40: 4009 | G40: 4009
B41: Additional paid-in capital | C41: 64848 | D41: 65795 | E41: 66556 | F41: 67684 | G41: 68770
B42: Reserve for esop debt retirement | C42: -1006 | D42: -916 | E42: -821 | F42: -737 | G42: -672
B43: Accumulated other comprehensive loss | C43: -13744 | D43: -12189 | E43: -12220 | F43: -11900 | G43: -12143
B44: Treasury stock, at cost (shares held: 2021 - 1,579.5, 2022 - 1,615.4, 2023 - 1,647.1, 2024 - 1,652.2; 2025 - 1,667.3) | C44: -114973 | D44: -123382 | E44: -129736 | F44: -133379 | G44: -138702
B45: Retained earnings | C45: 106374 | D45: 112429 | E45: 118170 | F45: 123811 | G45: 129973
...

Sheet Ratio Analysis
B1: Profitability Ratios
B3: Ratios | C3: 2021 | D3: 2022 | E3: 2023 | F3: 2024 | G3: 2025
B4: Return on Assets | D4: ='Income Statment (Trend)'!D10/(('Balance sheet (KPIs)'!C20+'Balance sheet (KPIs)'!D20)/2) -> 0.15062892 | E4: ='Income Statment (Trend)'!E10/(('Balance sheet (KPIs)'!D20+'Balance sheet (KPIs)'!E20)/2) -> 0.15236287 | F4: ='Income Statment (Trend)'!F10/(('Balance sheet (KPIs)'!E20+'Balance sheet (KPIs)'!F20)/2) -> 0.15250885 | G4: ='Income Statment (Trend)'!G10/(('Balance sheet (KPIs)'!F20+'Balance sheet (KPIs)'!G20)/2) -> 0.16519319
B5: Return on Equity | D5: ='Income Statment (Trend)'!C18/(('Balance sheet (KPIs)'!C47+'Balance sheet (KPIs)'!D47)/2) -> 0.30598451 | E5: ='Income Statment (Trend)'!D18/(('Balance sheet (KPIs)'!D47+'Balance sheet (KPIs)'!E47)/2) -> 0.31393009 | F5: ='Income Statment (Trend)'!E18/(('Balance sheet (KPIs)'!E47+'Balance sheet (KPIs)'!F47)/2) -> 0.30019258 | G5: ='Income Statment (Trend)'!F18/(('Balance sheet (KPIs)'!F47+'Balance sheet (KPIs)'!G47)/2) -> 0.28935368
B6: Return on Total Capital | D6: ='Income Statment (Trend)'!D10/(('Balance sheet (KPIs)'!C47+'Balance sheet (KPIs)'!D47)/2) -> 0.38099414 | E6: ='Income Statment (Trend)'!E10/(('Balance sheet (KPIs)'!D47+'Balance sheet (KPIs)'!E47)/2) -> 0.38616254 | F6: ='Income Statment (Trend)'!F10/(('Balance sheet (KPIs)'!E47+'Balance sheet (KPIs)'!F47)/2) -> 0.37992707 | G6: ='Income Statment (Trend)'!G10/(('Balance sheet (KPIs)'!F47+'Balance sheet (KPIs)'!G47)/2) -> 0.39771302
B8: Valuation Ratios
B9: Market Price | C9: 130.027 | D9: 141.856 | E9: 151.74 | F9: 164.92 | G9: 159.32
B10: Shares Outstanding | C10: =2427424874/1000000 -> 2427.4249 | D10: =2389553883/1000000 -> 2389.5539 | E10: =2357306187/1000000 -> 2357.3062 | F10: =2354050987/1000000 -> 2354.051 | G10: =2342371488/1000000 -> 2342.3715
B11: Earning per share | C11: ='Income Statment (Trend)'!C20/'Ratio Analysis'!C10 -> 5.7818473 | D11: ='Income Statment (Trend)'!D20/'Ratio Analysis'!D10 -> 6.0517572 | E11: ='Income Statment (Trend)'!E20/'Ratio Analysis'!E10 -> 6.0963655 | F11: ='Income Statment (Trend)'!F20/'Ratio Analysis'!F10 -> 6.1999507 | G11: ='Income Statment (Trend)'!G20/'Ratio Analysis'!G10 -> 6.6953513
B12: Price to Earnings | C12: =C9/C11 -> 22.488833 | D12: =D9/D11 -> 23.440464 | E12: =E9/E11 -> 24.89024 | F12: =F9/F11 -> 26.600212 | G12: =G9/G11 -> 23.795615
B13: Dividends | C13: 8263 | D13: 8770 | E13: 8999 | F13: 9312 | G13: 9872
B14: Dividend per share | C14: =C13/C10 -> 3.4040188 | D14: =D13/D10 -> 3.6701411 | E14: =E13/E10 -> 3.8174931 | F14: =F13/F10 -> 3.9557342 | G14: =G13/G10 -> 4.2145322
B15: Dividend Yeild | C15: =C14/C9 -> 0.026179323 | D15: =D14/D9 -> 0.025872301 | E15: =E14/E9 -> 0.02515812 | F15: =F14/F9 -> 0.023985776 | G15: =G14/G9 -> 0.026453252
B16: Retention | C16: =('Income Statment (Trend)'!C20-'Ratio Analysis'!C13)/'Income Statment (Trend)'!C20 -> 0.41125757 | D16: =('Income Statment (Trend)'!D20-'Ratio Analysis'!D13)/'Income Statment (Trend)'!D20 -> 0.39354125 | E16: =('Income Statment (Trend)'!E20-'Ratio Analysis'!E13)/'Income Statment (Trend)'!E20 -> 0.37380836 | F16: =('Income Statment (Trend)'!F20-'Ratio Analysis'!F13)/'Income Statment (Trend)'!F20 -> 0.36197328 | G16: =('Income Statment (Trend)'!G20-'Ratio Analysis'!G13)/'Income Statment (Trend)'!G20 -> 0.3705286
B17: Dividend Payout | C17: =C13/'Income Statment (Trend)'!C20 -> 0.58874243 | D17: =D13/'Income Statment (Trend)'!D20 -> 0.60645875 | E17: =E13/'Income Statment (Trend)'!E20 -> 0.62619164 | F17: =F13/'Income Statment (Trend)'!F20 -> 0.63802672 | G17: =G13/'Income Statment (Trend)'!G20 -> 0.6294714
B18: Sustainable Growth Rate | D18: =D16*D5 -> 0.12041753 | E18: =E16*E5 -> 0.11734969 | F18: =F16*F5 -> 0.10866169 | G18: =G16*G5 -> 0.10721381
B20: Activity Ratios
B21: Receivables turnover | D21: ='Income Statment (Trend)'!D5/(('Balance sheet (KPIs)'!C8+'Balance sheet (KPIs)'!D8)/2) -> 16.251925 | E21: ='Income Statment (Trend)'!E5/(('Balance sheet (KPIs)'!D8+'Balance sheet (KPIs)'!E8)/2) -> 15.452421 | F21: ='Income Statment (Trend)'!F5/(('Balance sheet (KPIs)'!E8+'Balance sheet (KPIs)'!F8)/2) -> 14.503236 | G21: ='Income Statment (Trend)'!G5/(('Balance sheet (KPIs)'!F8+'Balance sheet (KPIs)'!G8)/2) -> 13.701374
B22: DSO | D22: =365/D21 -> 22.458877 | E22: =365/E21 -> 23.620894 | F22: =365/F21 -> 25.166798 | G22: =365/G21 -> 26.639665
B23: Inventory turnover | D23: =-('Income Statment (Trend)'!D6/(('Balance sheet (KPIs)'!C13+'Balance sheet (KPIs)'!D13)/2)) -> 6.5324243 | E23: =-('Income Statment (Trend)'!E6/(('Balance sheet (KPIs)'!D13+'Balance sheet (KPIs)'!E13)/2)) -> 6.1098807 | F23: =-('Income Statment (Trend)'!F6/(('Balance sheet (KPIs)'!E13+'Balance sheet (KPIs)'!F13)/2)) -> 5.7985663 | G23: =-('Income Statment (Trend)'!G6/(('Balance sheet (KPIs)'!F13+'Balance sheet (KPIs)'!G13)/2)) -> 5.6516785
B24: DIO | D24: =365/D23 -> 55.875122 | E24: =365/E23 -> 59.739301 | F24: =365/F23 -> 62.946595 | G24: =365/G23 -> 64.582584
B25: Payables turnover | D25: =-('Income Statment (Trend)'!D6/(('Balance sheet (KPIs)'!C24+'Balance sheet (KPIs)'!D24)/2)) -> 2.9478358 | E25: =-('Income Statment (Trend)'!E6/(('Balance sheet (KPIs)'!D24+'Balance sheet (KPIs)'!E24)/2)) -> 2.9009498 | F25: =-('Income Statment (Trend)'!F6/(('Balance sheet (KPIs)'!E24+'Balance sheet (KPIs)'!F24)/2)) -> 2.7266538 | G25: =-('Income Statment (Trend)'!G6/(('Balance sheet (KPIs)'!F24+'Balance sheet (KPIs)'!G24)/2)) -> 2.6912491
B26: DPO | D26: =365/D25 -> 123.81965 | E26: =365/E25 -> 125.82086 | F26: =365/F25 -> 133.86371 | G26: =365/G25 -> 135.62476
B27: Cash Conversion Cycle | D27: =D22+D24+D26 -> 202.15365 | E27: =E22+E24+E26 -> 209.18105 | F27: =F22+F24+F26 -> 221.97711 | G27: =G22+G24+G26 -> 226.84701
B28: Fixed asset turnover | D28: ='Income Statment (Trend)'!D5/(('Balance sheet (KPIs)'!C16+'Balance sheet (KPIs)'!D16)/2) -> 3.7399781 | E28: ='Income Statment (Trend)'!E5/(('Balance sheet (KPIs)'!D16+'Balance sheet (KPIs)'!E16)/2) -> 3.8050297 | F28: ='Income Statment (Trend)'!F5/(('Balance sheet (KPIs)'!E16+'Balance sheet (KPIs)'!F16)/2) -> 3.814666 | G28: ='Income Statment (Trend)'!G5/(('Balance sheet (KPIs)'!F16+'Balance sheet (KPIs)'!G16)/2) -> 3.6606224
B29: Working capital Turnover | D29: ='Income Statment (Trend)'!D5/(('Balance sheet (KPIs)'!J8+'Balance sheet (KPIs)'!K8)/2) -> -7.4700265 | E29: ='Income Statment (Trend)'!E5/(('Balance sheet (KPIs)'!K8+'Balance sheet (KPIs)'!L8)/2) -> -6.6845452 | F29: ='Income Statment (Trend)'!F5/(('Balance sheet (KPIs)'!L8+'Balance sheet (KPIs)'!M8)/2) -> -7.6308908 | G29: ='Income Statment (Trend)'!G5/(('Balance sheet (KPIs)'!M8+'Balance sheet (KPIs)'!N8)/2) -> -8.6074346
B30: Total Asset turnover | D30: ='Income Statment (Trend)'!D5/(('Balance sheet (KPIs)'!C20+'Balance sheet (KPIs)'!D20)/2) -> 0.67807116 | E30: ='Income Statment (Trend)'!E5/(('Balance sheet (KPIs)'!D20+'Balance sheet (KPIs)'!E20)/2) -> 0.68901893 | F30: ='Income Statment (Trend)'!F5/(('Balance sheet (KPIs)'!E20+'Balance sheet (KPIs)'!F20)/2) -> 0.69111304 | G30: ='Income Statment (Trend)'!G5/(('Balance sheet (KPIs)'!F20+'Balance sheet (KPIs)'!G20)/2) -> 0.680805
B31: Equity turnover | D31: ='Income Statment (Trend)'!D5/(('Balance sheet (KPIs)'!C47+'Balance sheet (KPIs)'!D47)/2) -> 1.7150832 | E31: ='Income Statment (Trend)'!E5/(('Balance sheet (KPIs)'!D47+'Balance sheet (KPIs)'!E47)/2) -> 1.7463133 | F31: ='Income Statment (Trend)'!F5/(('Balance sheet (KPIs)'!E47+'Balance sheet (KPIs)'!F47)/2) -> 1.7216873 | G31: ='Income Statment (Trend)'!G5/(('Balance sheet (KPIs)'!F47+'Balance sheet (KPIs)'!G47)/2) -> 1.6390809

Sheet Cash flow Statment
B1: Cash Flow Statement
B4: $ in millions | C4: 2021 | D4: 2022 | E4: 2023 | F4: 2024 | G4: 2025 | J4: 2021 | K4: 2022 | L4: 2023 | M4: 2024 | N4: 2025
B5: Cash, cash equivalents and restricted cash, beginning of year | C5: 16181 | D5: 10288 | E5: 7214 | F5: 8246 | G5: 9482 | I5: CFO | J5: =C19 -> 18371 | K5: =D19 -> 16723 | L5: =E19 -> 16848 | M5: =F19 -> 19846 | N5: =G19 -> 17817
B6: Operating activities | I6: Interest expense | J6: =-'Income Statment (Trend)'!C11 -> 502 | K6: =-'Income Statment (Trend)'!D11 -> 439 | L6: =-'Income Statment (Trend)'!E11 -> 756 | M6: =-'Income Statment (Trend)'!F11 -> 925 | N6: =-'Income Statment (Trend)'!G11 -> 907
B7: Net earnings | C7: 14352 | D7: 14793 | E7: 14738 | F7: 14974 | G7: 16065 | I7: Tax rate | J7: ='Income Statment (Trend)'!C23 -> 0.185 | K7: ='Income Statment (Trend)'!D23 -> 0.178 | L7: ='Income Statment (Trend)'!E23 -> 0.197 | M7: ='Income Statment (Trend)'!F23 -> 0.202 | N7: ='Income Statment (Trend)'!G23 -> 0.203
B8: Depreciation and amortization | C8: 2735 | D8: 2807 | E8: 2714 | F8: 2896 | G8: 2847 | I8: Tax paid | J8: =-'Income Statment (Trend)'!C15 -> 3263 | K8: =-'Income Statment (Trend)'!D15 -> 3202 | L8: =-'Income Statment (Trend)'!E15 -> 3615 | M8: =-'Income Statment (Trend)'!F15 -> 3787 | N8: =-'Income Statment (Trend)'!G15 -> 4102
B9: Loss on early extinguishment of debt | C9: 512 | D9: 0 | E9: 0 | F9: 0 | G9: 0 | I9: CFI | J9: =-C25 -> 2834 | K9: =-D25 -> 4424 | L9: =-E25 -> 3500 | M9: =-F25 -> 3504 | N9: =-G25 -> 3818
B10: Share-based compensation expense | C10: 540 | D10: 528 | E10: 545 | F10: 562 | G10: 476 | I10: Additions to long-term debt | J10: =C33 -> 4417 | K10: =D33 -> 4385 | L10: =E33 -> 3997 | M10: =F33 -> 3197 | N10: =G33 -> 2237
B11: Deferred income taxes | C11: -258 | D11: -402 | E11: -453 | F11: -244 | G11: 149 | I11: Reductions in long-term debt (1) | J11: =-C34 -> 4987 | K11: =-D34 -> 2343 | L11: =-E34 -> 1878 | M11: =-F34 -> 2335 | N11: =-G34 -> 1977
B12: Loss/(gain) on sale of assets | C12: -16 | D12: -85 | E12: -40 | F12: -215 | G12: 755 | I12: FCFF | J12: =J5+J6*(1-J7)-J9 -> 15946.13 | K12: =K5+K6*(1-K7)-K9 -> 12659.858 | L12: =L5+L6*(1-L7)-L9 -> 13955.068 | M12: =M5+M6*(1-M7)-M9 -> 17080.15 | N12: =N5+N6*(1-N7)-N9 -> 14721.879
B13: Indefinite-lived intangible asset impairment charge | E13: 0 | F13: 1341 | G13: 0 | I13: FCFE | J13: =J12-J6*(1-J7)+J10-J11 -> 14967 | K13: =K12-K6*(1-K7)+K10-K11 -> 14341 | L13: =L12-L6*(1-L7)+L10-L11 -> 15467 | M13: =M12-M6*(1-M7)+M10-M11 -> 17204 | N13: =N12-N6*(1-N7)+N10-N11 -> 14259
B14: Change in accounts receivable | C14: -342 | D14: -694 | E14: -307 | F14: -766 | G14: 45
B15: Change in inventories | C15: -309 | D15: -1247 | E15: -119 | F15: -70 | G15: -324
B16: Change in accounts payable and accrued and other liabilities | C16: 1391 | D16: 1429 | E16: 313 | F16: 878 | G16: -542 | I16: Total operating activities | J16: 18371 | K16: 16723 | L16: 16848 | M16: 19846 | N16: 17817
B17: Change in other operating assets and liabilities | C17: -369 | D17: -635 | E17: -1107 | I17: Total investing activities | J17: =-C25 -> 2834 | K17: =-D25 -> 4424 | L17: =-E25 -> 3500 | M17: =-F25 -> 3504 | N17: =-G25 -> 3818
B18: Other | C18: 135 | D18: 229 | E18: 564 | F18: 491 | G18: -1653 | I18: Total financing activities | J18: =-C37 -> 21531 | K18: =-D37 -> 14876 | L18: =-E37 -> 12146 | M18: =-F37 -> 14855 | N18: =-G37 -> 14036
B19: Total operating activities | C19: 18371 | D19: 16723 | E19: 16848 | F19: 19846 | G19: 17817
B20: Investing activities | I20: Performance Ratios
B21: Capital expenditures | C21: -2787 | D21: -3156 | E21: -3062 | F21: -3322 | G21: -3773 | I21: Casf flow to revenue | J21: =J16/'Income Statment (Trend)'!C5 -> 0.24134896 | K21: =K16/'Income Statment (Trend)'!D5 -> 0.20855001 | L21: =L16/'Income Statment (Trend)'!E5 -> 0.20544838 | M21: =M16/'Income Statment (Trend)'!F5 -> 0.23615226 | N21: =N16/'Income Statment (Trend)'!G5 -> 0.21139244
B22: Proceeds from asset sales | C22: 42 | D22: 110 | E22: 46 | F22: 346 | G22: 107 | I22: Cash to Income | J22: =J16/'Income Statment (Trend)'!C10 -> 1.0214055 | K22: =K16/'Income Statment (Trend)'!D10 -> 0.93880874 | L22: =L16/'Income Statment (Trend)'!E10 -> 0.92908349 | M22: =M16/'Income Statment (Trend)'!F10 -> 1.0701537 | N22: =N16/'Income Statment (Trend)'!G10 -> 0.87120434
B23: Acquisitions, net of cash acquired | C23: -34 | D23: -1381 | E23: -765 | F23: -21 | G23: -11 | I23: Cash return on assets | K23: =K16/(('Balance sheet (KPIs)'!C20+'Balance sheet (KPIs)'!D20)/2) -> 0.14141175 | L23: =L16/(('Balance sheet (KPIs)'!D20+'Balance sheet (KPIs)'!E20)/2) -> 0.14155783 | M23: =M16/(('Balance sheet (KPIs)'!E20+'Balance sheet (KPIs)'!F20)/2) -> 0.16320791 | N23: =N16/(('Balance sheet (KPIs)'!F20+'Balance sheet (KPIs)'!G20)/2) -> 0.14391703
B24: Other investing activity | C24: -55 | D24: 3 | E24: 281 | F24: -507 | G24: -141 | I24: Cash return on equity | K24: =K16/(('Balance sheet (KPIs)'!C47+'Balance sheet (KPIs)'!D47)/2) -> 0.35768063 | L24: =L16/(('Balance sheet (KPIs)'!D47+'Balance sheet (KPIs)'!E47)/2) -> 0.35877724 | M24: =M16/(('Balance sheet (KPIs)'!E47+'Balance sheet (KPIs)'!F47)/2) -> 0.40658035 | N24: =N16/(('Balance sheet (KPIs)'!F47+'Balance sheet (KPIs)'!G47)/2) -> 0.34648931
B25: Total investing activities | C25: -2834 | D25: -4424 | E25: -3500 | F25: -3504 | G25: -3818 | I25: Cash flow per share | J25: =(J16-'Income Statment (Trend)'!C19)/'Balance sheet (KPIs)'!C54 -> 7.3404169e-06 | K25: =(K16-'Income Statment (Trend)'!D19)/'Balance sheet (KPIs)'!D54 -> 6.8215575e-06 | L25: =(L16-'Income Statment (Trend)'!E19)/'Balance sheet (KPIs)'!E54 -> 6.9951862e-06 | M25: =(M16-'Income Statment (Trend)'!F19)/'Balance sheet (KPIs)'!F54 -> 8.2886318e-06 | N25: =(N16-'Income Statment (Trend)'!G19)/'Balance sheet (KPIs)'!G54 -> 7.457555e-06
B26: Financing activities
B27: Dividends to shareholders | C27: -8263 | D27: -8770 | E27: -8999 | F27: -9312 | G27: -9872 | I27: Interest coverage ratio | J27: =(J5+J6+J8)/J6 -> 44.095618 | K27: =(K5+K6+K8)/K6 -> 46.387244 | L27: =(L5+L6+L8)/L6 -> 28.06746 | M27: =(M5+M6+M8)/M6 -> 26.549189 | N27: =(N5+N6+N8)/N6 -> 25.166483
B28: Additions to short-term debt with original maturities of more than | I28: Debt Coverage Ratio | J28: =J5/'Balance sheet (KPIs)'!C31 -> 0.25285948 | K28: =K5/'Balance sheet (KPIs)'!D31 -> 0.23769793 | L28: =L5/'Balance sheet (KPIs)'!E31 -> 0.2284041 | M28: =M5/'Balance sheet (KPIs)'!F31 -> 0.27636435 | N28: =N5/'Balance sheet (KPIs)'!G31 -> 0.24424917
B29: Three months | C29: 7675 | D29: 10411 | E29: 17168 | F29: 3528 | G29: 8020
B30: Reductions in short-term debt with original maturities of more than
B31: Three months | C31: -7577 | D31: -11478 | E31: -13031 | F31: -7689 | G31: -6512
B32: Net additions/(reductions) to other short-term debt | C32: -3431 | D32: 917 | E32: -3319 | F32: 857 | G32: -1138
B33: Additions to long-term debt | C33: 4417 | D33: 4385 | E33: 3997 | F33: 3197 | G33: 2237
B34: Reductions in long-term debt (1) | C34: -4987 | D34: -2343 | E34: -1878 | F34: -2335 | G34: -1977
B35: Treasury stock purchases | C35: -11009 | D35: -10003 | E35: -7353 | F35: -5006 | G35: -6500
B36: Impact of stock options and other | C36: 1644 | D36: 2005 | E36: 1269 | F36: 1905 | G36: 1707
B37: Total financing activities | C37: -21531 | D37: -14876 | E37: -12146 | F37: -14855 | G37: -14036
B38: Effect of exchange rate changes on cash, cash equivalents and
B39: Restricted cash | C39: 101 | D39: -497 | E39: -170 | F39: -251 | G39: 112
B40: Change in cash, cash equivalents and restricted cash | C40: -5893 | D40: -3074 | E40: 1032 | F40: 1235 | G40: 75
B41: Cash, cash equivalents and restricted cash, end of year | C41: 10288 | D41: 7214 | E41: 8246 | F41: 9482 | G41: 9556

Sheet DCF
B1: DCF Valuation
B3: Cost of Debt | C3: 0.033
B4: CAPM
B5: Rfisk free rate | C5: 0.042
B6: Beta | C6: 0.43
B7: Market return | C7: 0.1
B8: Cost of Equity | C8: =C5+C6*(C7-C5) -> 0.06694
B9: Tax rate | C9: ='Income Statment (Trend)'!G23 -> 0.203
B10: WACC | C10: =(F20/(F20+G20)*(C8))+(G20/(F20+G20)*(C3*(1-C9))) -> 0.050513363 | D10: 0.07 | E10: (alternative)
B11: Growth Rate | C11: =AVERAGE('Income Statment (Trend)'!I5:L5) -> 0.025961783
B13: WACC
B14: Year | C14: Equity | D14: Debt | E14: Total
B15: 2021 | C15: ='Balance sheet (KPIs)'!C47 -> 46654 | D15: ='Balance sheet (KPIs)'!C28+'Balance sheet (KPIs)'!C26 -> 31988 | E15: =C15+D15 -> 78642 | F15: =C15/$E15 -> 0.59324534 | G15: =D15/$E15 -> 0.40675466
B16: 2022 | C16: ='Balance sheet (KPIs)'!D47 -> 46854 | D16: ='Balance sheet (KPIs)'!D28+'Balance sheet (KPIs)'!D26 -> 31493 | E16: =C16+D16 -> 78347 | F16: =C16/$E16 -> 0.59803183 | G16: =D16/$E16 -> 0.40196817
B17: 2023 | C17: ='Balance sheet (KPIs)'!E47 -> 47065 | D17: ='Balance sheet (KPIs)'!E28+'Balance sheet (KPIs)'!E26 -> 34607 | E17: =C17+D17 -> 81672 | F17: =C17/$E17 -> 0.57626849 | G17: =D17/$E17 -> 0.42373151
B18: 2024 | C18: ='Balance sheet (KPIs)'!F47 -> 50559 | D18: ='Balance sheet (KPIs)'!F28+'Balance sheet (KPIs)'!F26 -> 32460 | E18: =C18+D18 -> 83019 | F18: =C18/$E18 -> 0.60900517 | G18: =D18/$E18 -> 0.39099483
B19: 2025 | C19: ='Balance sheet (KPIs)'!G47 -> 52284 | D19: ='Balance sheet (KPIs)'!G28+'Balance sheet (KPIs)'!G26 -> 34508 | E19: =C19+D19 -> 86792 | F19: =C19/$E19 -> 0.60240575 | G19: =D19/$E19 -> 0.39759425
B20: Average weights | F20: =AVERAGE(F15:F19) -> 0.59579132 | G20: =AVERAGE(G15:G19) -> 0.40420868
B23: S.NO | C23: 0 | D23: 1 | E23: 2 | F23: 3 | G23: 4 | H23: 5 | I23: 6 | J23: 7 | K23: 8 | L23: 9 | M23: 10
B24: Period | C24: 2025 | D24: 2026 | E24: 2027 | F24: 2028 | G24: 2029 | H24: 2030 | I24: 2031 | J24: 2032 | K24: 2033 | L24: 2034 | M24: 2035
B25: FCFF | C25: ='Cash flow Statment'!N12 -> 14721.879 | D25: =C25*(1+$C11) -> 15104.085 | E25: =D25*(1+$C11) -> 15496.214 | F25: =E25*(1+$C11) -> 15898.524 | G25: =F25*(1+$C11) -> 16311.278 | H25: =G25*(1+$C11) -> 16734.747 | I25: =H25*(1+$C11) -> 17169.211 | J25: =I25*(1+$C11) -> 17614.955 | K25: =J25*(1+$C11) -> 18072.27 | ... M25: =L25*(1+$C11) -> 19022.828
D26: =PV($C10,D23,0,-D25,0) -> 14377.814 | E26: =PV($C10,E23,0,-E25,0) -> 14041.789 | F26: =PV($C10,F23,0,-F25,0) -> 13713.618 | G26: =PV($C10,G23,0,-G25,0) -> 13393.117 | H26: =PV($C10,H23,0,-H25,0) -> 13080.106 | I26: =PV($C10,I23,0,-I25,0) -> 12774.41 | J26: =PV($C10,J23,0,-J25,0) -> 12475.859 | K26: =PV($C10,K23,0,-K25,0) -> 12184.285 | ... M26: =PV($C10,M23,0,-M25,0) -> 11621.422
C27: =SUM(D26:M26) -> 129561.95
B28: PV of Cash flows | C28: =C25+C27 -> 144283.82
B29: Terminal value (PV) | C29: =PV(C10,M23,0,-M29,0) -> 485636.14 | M29: =(M25*(1+C11))/(C10-C11) -> 794926.21
B30: Enterprise Value | C30: =C28+C29 -> 629919.97
B31: Approx | C31: 630 billion
B33: Equity Value | C33: =C30-(('Balance sheet (KPIs)'!G28+'Balance sheet (KPIs)'!G26)-'Cash flow Statment'!G41) -> 604967.97
B34: Price Per share | C34: =C33/'Balance sheet (KPIs)'!G55 -> 257.42222

Sheet Peer comparision and Industry
B1: 2025
B2: KPIs | C2: P&G | D2: Unilever | E2: Colgate-Palmolive | F2: Reckitt Benckiser | G2: Kimberly-Clark
A3: 1 | B3: ='Income Statment (Common Size)'!B23 -> Net Profit Margin | C3: ='Income Statment (Common Size)'!G23 -> 0.18952589 | D3: 16.5 | E3: 10.5 | F3: 14 | G3: 12.6
A4: 2 | B4: ='Balance sheet (KPIs)'!I5 -> Current Ratio | C4: ='Balance sheet (KPIs)'!N5 -> 0.70419879 | D4: 0.78 | E4: 0.83 | F4: 0.74 | G4: 0.8
A5: 3 | B5: ='Balance sheet (KPIs)'!I10 -> Debt to equity | C5: ='Balance sheet (KPIs)'!N10 -> 1.3951878 | D5: 1.82 | E5: 147.9 | F5: 1.65 | G5: 4.79
A6: 4 | B6: ='Balance sheet (KPIs)'!I11 -> Debt to capital | C6: ='Balance sheet (KPIs)'!N11 -> 0.37052327 | D6: 0.48 | E6: 0.99 | F6: 0.45 | G6: 0.62
A7: 5 | B7: ='Balance sheet (KPIs)'!I12 -> Debt to Assets | C7: ='Balance sheet (KPIs)'!N12 -> 0.58249156 | D7: 0.61 | E7: 0.52 | F7: 0.55 | G7: 0.64
A8: 6 | B8: ='Ratio Analysis'!B11 -> Earning per share | C8: ='Ratio Analysis'!G11 -> 6.6953513 | D8: 3.25 | E8: 3.45 | F8: 3.1 | G8: 6.1
A9: 7 | B9: ='Ratio Analysis'!B12 -> Price to Earnings | C9: ='Ratio Analysis'!G12 -> 23.795615 | D9: 19.6 | E9: 35.3 | F9: 21.4 | G9: 23.2
A10: 8 | B10: ='Ratio Analysis'!B14 -> Dividend per share | C10: ='Ratio Analysis'!G14 -> 4.2145322 | D10: 1.87 | E10: 2 | F10: 2.12 | G10: 4.8
A11: 9 | B11: ='Ratio Analysis'!B17 -> Dividend Payout | C11: ='Ratio Analysis'!G17 -> 0.6294714 | D11: 65 | E11: 75 | F11: 60 | G11: 78
A12: 10 | B12: ='Cash flow Statment'!I28 -> Debt Coverage Ratio | C12: ='Cash flow Statment'!N28 -> 0.24424917 | D12: 0.22 | E12: 0.18 | F12: 0.2 | G12: 0.21
B17: Ratio | C17: P&G | D17: Industry Avg | E17: Interpretation
B18: Net Profit Margin | C18: 0.1895 | D18: 10–12% | E18: Much stronger profitability
B19: Current Ratio | C19: 0.7 | D19: 1.2 | E19: Slightly lower liquidity
B20: Debt to Equity | C20: 1.4 | D20: 1.2 | E20: Higher leverage
B21: Debt to Assets | C21: 0.58 | D21: 0.55 | E21: Normal
B22: P/E | C22: 23.8 | D22: 25 | E22: Fair valuation
B23: Dividend Payout | C23: 0.63 | D23: 55–70% | E23: Normal
B24: Debt Coverage | C24: 0.24 | D24: 0.3 | E24: Slightly weaker cash coverage
